[2025-08-08 18:09:39 +0530] [1] [INFO] Starting gunicorn 21.2.0
[2025-08-08 18:09:39 +0530] [1] [INFO] Listening at: http://0.0.0.0:8000 (1)
[2025-08-08 18:09:39 +0530] [1] [INFO] Using worker: uvicorn.workers.UvicornWorker
[2025-08-08 18:09:39 +0530] [11] [INFO] Booting worker with pid: 11
[2025-08-08 18:09:39 +0530] [12] [INFO] Booting worker with pid: 12
[2025-08-08 18:09:43 +0530] [11] [INFO] Started server process [11]
[2025-08-08 18:09:43 +0530] [11] [INFO] Waiting for application startup.
[2025-08-08 18:09:43 +0530] [12] [INFO] Started server process [12]
[2025-08-08 18:09:43 +0530] [12] [INFO] Waiting for application startup.
[2025-08-08 18:09:44 +0530] [11] [INFO] Application startup complete.
[2025-08-08 18:09:44 +0530] [12] [INFO] Application startup complete.
[2025-08-08 19:10:53 +0530] [1] [INFO] Handling signal: term
[2025-08-08 19:10:53 +0530] [11] [INFO] Shutting down
[2025-08-08 19:10:53 +0530] [11] [INFO] Error while closing socket [Errno 9] Bad file descriptor
[2025-08-08 19:10:53 +0530] [12] [INFO] Shutting down
[2025-08-08 19:10:53 +0530] [12] [INFO] Error while closing socket [Errno 9] Bad file descriptor
[2025-08-08 19:10:53 +0530] [11] [INFO] Waiting for application shutdown.
[2025-08-08 19:10:53 +0530] [12] [INFO] Waiting for application shutdown.
[2025-08-08 19:10:53 +0530] [11] [INFO] Application shutdown complete.
[2025-08-08 19:10:53 +0530] [11] [INFO] Finished server process [11]
[2025-08-08 19:10:53 +0530] [12] [INFO] Application shutdown complete.
[2025-08-08 19:10:53 +0530] [12] [INFO] Finished server process [12]
[2025-08-08 19:10:53 +0530] [11] [INFO] Worker exiting (pid: 11)
[2025-08-08 19:10:53 +0530] [12] [INFO] Worker exiting (pid: 12)
[2025-08-08 19:10:54 +0530] [1] [INFO] Shutting down: Master
[2025-08-10 15:27:16 +0530] [1] [INFO] Starting gunicorn 21.2.0
[2025-08-10 15:27:16 +0530] [1] [INFO] Listening at: http://0.0.0.0:8000 (1)
[2025-08-10 15:27:16 +0530] [1] [INFO] Using worker: uvicorn.workers.UvicornWorker
[2025-08-10 15:27:16 +0530] [12] [INFO] Booting worker with pid: 12
[2025-08-10 15:27:17 +0530] [13] [INFO] Booting worker with pid: 13
[2025-08-10 15:27:21 +0530] [12] [INFO] Started server process [12]
[2025-08-10 15:27:21 +0530] [12] [INFO] Waiting for application startup.
[2025-08-10 15:27:21 +0530] [13] [INFO] Started server process [13]
[2025-08-10 15:27:21 +0530] [13] [INFO] Waiting for application startup.
[2025-08-10 15:27:21 +0530] [12] [INFO] Application startup complete.
[2025-08-10 15:27:21 +0530] [13] [INFO] Application startup complete.
[2025-08-10 15:50:57 +0530] [1] [INFO] Handling signal: term
[2025-08-10 15:50:57 +0530] [13] [INFO] Shutting down
[2025-08-10 15:50:57 +0530] [13] [INFO] Error while closing socket [Errno 9] Bad file descriptor
[2025-08-10 15:50:57 +0530] [12] [INFO] Shutting down
[2025-08-10 15:50:57 +0530] [12] [INFO] Error while closing socket [Errno 9] Bad file descriptor
[2025-08-10 15:50:57 +0530] [12] [INFO] Waiting for application shutdown.
[2025-08-10 15:50:57 +0530] [13] [INFO] Waiting for application shutdown.
[2025-08-10 15:50:57 +0530] [13] [INFO] Application shutdown complete.
[2025-08-10 15:50:57 +0530] [12] [INFO] Application shutdown complete.
[2025-08-10 15:50:57 +0530] [13] [INFO] Finished server process [13]
[2025-08-10 15:50:57 +0530] [12] [INFO] Finished server process [12]
[2025-08-10 15:50:57 +0530] [12] [INFO] Worker exiting (pid: 12)
[2025-08-10 15:50:57 +0530] [13] [INFO] Worker exiting (pid: 13)
[2025-08-10 15:50:58 +0530] [1] [INFO] Shutting down: Master
[2025-08-10 15:50:58 +0530] [1] [INFO] Starting gunicorn 21.2.0
[2025-08-10 15:50:58 +0530] [1] [INFO] Listening at: http://0.0.0.0:8000 (1)
[2025-08-10 15:50:58 +0530] [1] [INFO] Using worker: uvicorn.workers.UvicornWorker
[2025-08-10 15:50:58 +0530] [12] [INFO] Booting worker with pid: 12
[2025-08-10 15:50:58 +0530] [13] [INFO] Booting worker with pid: 13
[2025-08-10 15:51:03 +0530] [13] [ERROR] Exception in worker process
Traceback (most recent call last):
  File "/usr/local/lib/python3.9/site-packages/sqlalchemy/engine/base.py", line 1969, in _exec_single_context
    self.dialect.do_execute(
  File "/usr/local/lib/python3.9/site-packages/sqlalchemy/engine/default.py", line 922, in do_execute
    cursor.execute(statement, parameters)
sqlite3.OperationalError: table users already exists

The above exception was the direct cause of the following exception:

Traceback (most recent call last):
  File "/usr/local/lib/python3.9/site-packages/gunicorn/arbiter.py", line 609, in spawn_worker
    worker.init_process()
  File "/usr/local/lib/python3.9/site-packages/uvicorn/workers.py", line 66, in init_process
    super(UvicornWorker, self).init_process()
  File "/usr/local/lib/python3.9/site-packages/gunicorn/workers/base.py", line 134, in init_process
    self.load_wsgi()
  File "/usr/local/lib/python3.9/site-packages/gunicorn/workers/base.py", line 146, in load_wsgi
    self.wsgi = self.app.wsgi()
  File "/usr/local/lib/python3.9/site-packages/gunicorn/app/base.py", line 67, in wsgi
    self.callable = self.load()
  File "/usr/local/lib/python3.9/site-packages/gunicorn/app/wsgiapp.py", line 58, in load
    return self.load_wsgiapp()
  File "/usr/local/lib/python3.9/site-packages/gunicorn/app/wsgiapp.py", line 48, in load_wsgiapp
    return util.import_app(self.app_uri)
  File "/usr/local/lib/python3.9/site-packages/gunicorn/util.py", line 371, in import_app
    mod = importlib.import_module(module)
  File "/usr/local/lib/python3.9/importlib/__init__.py", line 127, in import_module
    return _bootstrap._gcd_import(name[level:], package, level)
  File "<frozen importlib._bootstrap>", line 1030, in _gcd_import
  File "<frozen importlib._bootstrap>", line 1007, in _find_and_load
  File "<frozen importlib._bootstrap>", line 986, in _find_and_load_unlocked
  File "<frozen importlib._bootstrap>", line 680, in _load_unlocked
  File "<frozen importlib._bootstrap_external>", line 850, in exec_module
  File "<frozen importlib._bootstrap>", line 228, in _call_with_frames_removed
  File "/app/app/main.py", line 39, in <module>
    Base.metadata.create_all(bind=engine)
  File "/usr/local/lib/python3.9/site-packages/sqlalchemy/sql/schema.py", line 5828, in create_all
    bind._run_ddl_visitor(
  File "/usr/local/lib/python3.9/site-packages/sqlalchemy/engine/base.py", line 3243, in _run_ddl_visitor
    conn._run_ddl_visitor(visitorcallable, element, **kwargs)
  File "/usr/local/lib/python3.9/site-packages/sqlalchemy/engine/base.py", line 2447, in _run_ddl_visitor
    visitorcallable(self.dialect, self, **kwargs).traverse_single(element)
  File "/usr/local/lib/python3.9/site-packages/sqlalchemy/sql/visitors.py", line 671, in traverse_single
    return meth(obj, **kw)
  File "/usr/local/lib/python3.9/site-packages/sqlalchemy/sql/ddl.py", line 919, in visit_metadata
    self.traverse_single(
  File "/usr/local/lib/python3.9/site-packages/sqlalchemy/sql/visitors.py", line 671, in traverse_single
    return meth(obj, **kw)
  File "/usr/local/lib/python3.9/site-packages/sqlalchemy/sql/ddl.py", line 952, in visit_table
    CreateTable(
  File "/usr/local/lib/python3.9/site-packages/sqlalchemy/sql/ddl.py", line 315, in _invoke_with
    return bind.execute(self)
  File "/usr/local/lib/python3.9/site-packages/sqlalchemy/engine/base.py", line 1416, in execute
    return meth(
  File "/usr/local/lib/python3.9/site-packages/sqlalchemy/sql/ddl.py", line 181, in _execute_on_connection
    return connection._execute_ddl(
  File "/usr/local/lib/python3.9/site-packages/sqlalchemy/engine/base.py", line 1528, in _execute_ddl
    ret = self._execute_context(
  File "/usr/local/lib/python3.9/site-packages/sqlalchemy/engine/base.py", line 1848, in _execute_context
    return self._exec_single_context(
  File "/usr/local/lib/python3.9/site-packages/sqlalchemy/engine/base.py", line 1988, in _exec_single_context
    self._handle_dbapi_exception(
  File "/usr/local/lib/python3.9/site-packages/sqlalchemy/engine/base.py", line 2343, in _handle_dbapi_exception
    raise sqlalchemy_exception.with_traceback(exc_info[2]) from e
  File "/usr/local/lib/python3.9/site-packages/sqlalchemy/engine/base.py", line 1969, in _exec_single_context
    self.dialect.do_execute(
  File "/usr/local/lib/python3.9/site-packages/sqlalchemy/engine/default.py", line 922, in do_execute
    cursor.execute(statement, parameters)
sqlalchemy.exc.OperationalError: (sqlite3.OperationalError) table users already exists
[SQL: 
CREATE TABLE users (
	id INTEGER NOT NULL, 
	username VARCHAR(50) NOT NULL, 
	password_hash VARCHAR(255) NOT NULL, 
	email VARCHAR(100), 
	is_active BOOLEAN, 
	is_admin BOOLEAN, 
	last_login DATETIME, 
	created_at DATETIME DEFAULT (CURRENT_TIMESTAMP), 
	updated_at DATETIME, 
	PRIMARY KEY (id)
)

]
(Background on this error at: https://sqlalche.me/e/20/e3q8)
[2025-08-10 15:51:03 +0530] [13] [INFO] Worker exiting (pid: 13)
[2025-08-10 15:51:03 +0530] [12] [INFO] Started server process [12]
[2025-08-10 15:51:03 +0530] [12] [INFO] Waiting for application startup.
[2025-08-10 15:51:03 +0530] [1] [ERROR] Worker (pid:13) exited with code 3
[2025-08-10 15:51:03 +0530] [12] [INFO] Application startup complete.
[2025-08-10 15:51:03 +0530] [12] [INFO] Shutting down
[2025-08-10 15:51:03 +0530] [12] [INFO] Error while closing socket [Errno 9] Bad file descriptor
[2025-08-10 15:51:03 +0530] [12] [INFO] Waiting for application shutdown.
[2025-08-10 15:51:03 +0530] [12] [INFO] Application shutdown complete.
[2025-08-10 15:51:03 +0530] [12] [INFO] Finished server process [12]
[2025-08-10 15:51:03 +0530] [12] [INFO] Worker exiting (pid: 12)
[2025-08-10 15:51:03 +0530] [1] [ERROR] Worker (pid:31) exited with code 120
[2025-08-10 15:51:03 +0530] [1] [ERROR] Worker (pid:31) exited with code 120.
[2025-08-10 15:51:03 +0530] [1] [ERROR] Shutting down: Master
[2025-08-10 15:51:03 +0530] [1] [ERROR] Reason: Worker failed to boot.
[2025-08-10 15:51:04 +0530] [1] [INFO] Starting gunicorn 21.2.0
[2025-08-10 15:51:04 +0530] [1] [INFO] Listening at: http://0.0.0.0:8000 (1)
[2025-08-10 15:51:04 +0530] [1] [INFO] Using worker: uvicorn.workers.UvicornWorker
[2025-08-10 15:51:04 +0530] [11] [INFO] Booting worker with pid: 11
[2025-08-10 15:51:04 +0530] [12] [INFO] Booting worker with pid: 12
[2025-08-10 15:51:08 +0530] [11] [INFO] Started server process [11]
[2025-08-10 15:51:08 +0530] [11] [INFO] Waiting for application startup.
[2025-08-10 15:51:08 +0530] [11] [INFO] Application startup complete.
[2025-08-10 15:51:08 +0530] [12] [INFO] Started server process [12]
[2025-08-10 15:51:08 +0530] [12] [INFO] Waiting for application startup.
[2025-08-10 15:51:08 +0530] [12] [INFO] Application startup complete.
[2025-08-10 16:05:09 +0530] [1] [INFO] Handling signal: term
[2025-08-10 16:05:09 +0530] [11] [INFO] Shutting down
[2025-08-10 16:05:09 +0530] [12] [INFO] Shutting down
[2025-08-10 16:05:09 +0530] [12] [INFO] Error while closing socket [Errno 9] Bad file descriptor
[2025-08-10 16:05:09 +0530] [11] [INFO] Error while closing socket [Errno 9] Bad file descriptor
[2025-08-10 16:05:09 +0530] [12] [INFO] Waiting for application shutdown.
[2025-08-10 16:05:09 +0530] [11] [INFO] Waiting for application shutdown.
[2025-08-10 16:05:09 +0530] [12] [INFO] Application shutdown complete.
[2025-08-10 16:05:09 +0530] [12] [INFO] Finished server process [12]
[2025-08-10 16:05:09 +0530] [11] [INFO] Application shutdown complete.
[2025-08-10 16:05:09 +0530] [11] [INFO] Finished server process [11]
[2025-08-10 16:05:09 +0530] [12] [INFO] Worker exiting (pid: 12)
[2025-08-10 16:05:09 +0530] [11] [INFO] Worker exiting (pid: 11)
[2025-08-10 16:05:09 +0530] [1] [INFO] Shutting down: Master
[2025-08-10 16:05:10 +0530] [1] [INFO] Starting gunicorn 21.2.0
[2025-08-10 16:05:10 +0530] [1] [INFO] Listening at: http://0.0.0.0:8000 (1)
[2025-08-10 16:05:10 +0530] [1] [INFO] Using worker: uvicorn.workers.UvicornWorker
[2025-08-10 16:05:10 +0530] [12] [INFO] Booting worker with pid: 12
[2025-08-10 16:05:10 +0530] [13] [INFO] Booting worker with pid: 13
[2025-08-10 16:05:14 +0530] [12] [INFO] Started server process [12]
[2025-08-10 16:05:14 +0530] [13] [INFO] Started server process [13]
[2025-08-10 16:05:14 +0530] [12] [INFO] Waiting for application startup.
[2025-08-10 16:05:14 +0530] [13] [INFO] Waiting for application startup.
[2025-08-10 16:05:15 +0530] [13] [INFO] Application startup complete.
[2025-08-10 16:05:15 +0530] [12] [INFO] Application startup complete.
[2025-08-10 16:22:44 +0530] [1] [INFO] Handling signal: term
[2025-08-10 16:22:44 +0530] [12] [INFO] Shutting down
[2025-08-10 16:22:44 +0530] [13] [INFO] Shutting down
[2025-08-10 16:22:44 +0530] [12] [INFO] Error while closing socket [Errno 9] Bad file descriptor
[2025-08-10 16:22:44 +0530] [13] [INFO] Error while closing socket [Errno 9] Bad file descriptor
[2025-08-10 16:22:44 +0530] [12] [INFO] Waiting for application shutdown.
[2025-08-10 16:22:44 +0530] [13] [INFO] Waiting for application shutdown.
[2025-08-10 16:22:44 +0530] [12] [INFO] Application shutdown complete.
[2025-08-10 16:22:44 +0530] [12] [INFO] Finished server process [12]
[2025-08-10 16:22:44 +0530] [13] [INFO] Application shutdown complete.
[2025-08-10 16:22:44 +0530] [13] [INFO] Finished server process [13]
[2025-08-10 16:22:44 +0530] [13] [INFO] Worker exiting (pid: 13)
[2025-08-10 16:22:44 +0530] [12] [INFO] Worker exiting (pid: 12)
[2025-08-10 16:22:44 +0530] [1] [INFO] Shutting down: Master
[2025-08-10 16:23:01 +0530] [1] [INFO] Starting gunicorn 21.2.0
[2025-08-10 16:23:01 +0530] [1] [INFO] Listening at: http://0.0.0.0:8000 (1)
[2025-08-10 16:23:01 +0530] [1] [INFO] Using worker: uvicorn.workers.UvicornWorker
[2025-08-10 16:23:01 +0530] [12] [INFO] Booting worker with pid: 12
[2025-08-10 16:23:01 +0530] [13] [INFO] Booting worker with pid: 13
[2025-08-10 16:23:02 +0530] [12] [ERROR] Exception in worker process
Traceback (most recent call last):
  File "/usr/local/lib/python3.9/site-packages/gunicorn/arbiter.py", line 609, in spawn_worker
    worker.init_process()
  File "/usr/local/lib/python3.9/site-packages/uvicorn/workers.py", line 66, in init_process
    super(UvicornWorker, self).init_process()
  File "/usr/local/lib/python3.9/site-packages/gunicorn/workers/base.py", line 134, in init_process
    self.load_wsgi()
  File "/usr/local/lib/python3.9/site-packages/gunicorn/workers/base.py", line 146, in load_wsgi
    self.wsgi = self.app.wsgi()
  File "/usr/local/lib/python3.9/site-packages/gunicorn/app/base.py", line 67, in wsgi
    self.callable = self.load()
  File "/usr/local/lib/python3.9/site-packages/gunicorn/app/wsgiapp.py", line 58, in load
    return self.load_wsgiapp()
  File "/usr/local/lib/python3.9/site-packages/gunicorn/app/wsgiapp.py", line 48, in load_wsgiapp
    return util.import_app(self.app_uri)
  File "/usr/local/lib/python3.9/site-packages/gunicorn/util.py", line 371, in import_app
    mod = importlib.import_module(module)
  File "/usr/local/lib/python3.9/importlib/__init__.py", line 127, in import_module
    return _bootstrap._gcd_import(name[level:], package, level)
  File "<frozen importlib._bootstrap>", line 1030, in _gcd_import
  File "<frozen importlib._bootstrap>", line 1007, in _find_and_load
  File "<frozen importlib._bootstrap>", line 986, in _find_and_load_unlocked
  File "<frozen importlib._bootstrap>", line 680, in _load_unlocked
  File "<frozen importlib._bootstrap_external>", line 850, in exec_module
  File "<frozen importlib._bootstrap>", line 228, in _call_with_frames_removed
  File "/app/app/main.py", line 9, in <module>
    from app.api import auth, dashboard, config, backup, archives, restore, schedule, logs, settings, health, events, repositories, ssh_keys
  File "/app/app/api/dashboard.py", line 11, in <module>
    from app.database.models import User, BackupJob, ScheduledJob, SystemLog
ImportError: cannot import name 'ScheduledJob' from 'app.database.models' (/app/app/database/models.py)
[2025-08-10 16:23:02 +0530] [12] [INFO] Worker exiting (pid: 12)
[2025-08-10 16:23:02 +0530] [1] [ERROR] Worker (pid:12) exited with code 3
[2025-08-10 16:23:02 +0530] [1] [ERROR] Worker (pid:13) was sent SIGTERM!
[2025-08-10 16:23:02 +0530] [1] [ERROR] Shutting down: Master
[2025-08-10 16:23:02 +0530] [1] [ERROR] Reason: Worker failed to boot.
[2025-08-10 16:23:03 +0530] [1] [INFO] Starting gunicorn 21.2.0
[2025-08-10 16:23:03 +0530] [1] [INFO] Listening at: http://0.0.0.0:8000 (1)
[2025-08-10 16:23:03 +0530] [1] [INFO] Using worker: uvicorn.workers.UvicornWorker
[2025-08-10 16:23:03 +0530] [12] [INFO] Booting worker with pid: 12
[2025-08-10 16:23:03 +0530] [13] [INFO] Booting worker with pid: 13
[2025-08-10 16:23:03 +0530] [12] [ERROR] Exception in worker process
Traceback (most recent call last):
  File "/usr/local/lib/python3.9/site-packages/gunicorn/arbiter.py", line 609, in spawn_worker
    worker.init_process()
  File "/usr/local/lib/python3.9/site-packages/uvicorn/workers.py", line 66, in init_process
    super(UvicornWorker, self).init_process()
  File "/usr/local/lib/python3.9/site-packages/gunicorn/workers/base.py", line 134, in init_process
    self.load_wsgi()
  File "/usr/local/lib/python3.9/site-packages/gunicorn/workers/base.py", line 146, in load_wsgi
    self.wsgi = self.app.wsgi()
  File "/usr/local/lib/python3.9/site-packages/gunicorn/app/base.py", line 67, in wsgi
    self.callable = self.load()
  File "/usr/local/lib/python3.9/site-packages/gunicorn/app/wsgiapp.py", line 58, in load
    return self.load_wsgiapp()
  File "/usr/local/lib/python3.9/site-packages/gunicorn/app/wsgiapp.py", line 48, in load_wsgiapp
    return util.import_app(self.app_uri)
  File "/usr/local/lib/python3.9/site-packages/gunicorn/util.py", line 371, in import_app
    mod = importlib.import_module(module)
  File "/usr/local/lib/python3.9/importlib/__init__.py", line 127, in import_module
    return _bootstrap._gcd_import(name[level:], package, level)
  File "<frozen importlib._bootstrap>", line 1030, in _gcd_import
  File "<frozen importlib._bootstrap>", line 1007, in _find_and_load
  File "<frozen importlib._bootstrap>", line 986, in _find_and_load_unlocked
  File "<frozen importlib._bootstrap>", line 680, in _load_unlocked
  File "<frozen importlib._bootstrap_external>", line 850, in exec_module
  File "<frozen importlib._bootstrap>", line 228, in _call_with_frames_removed
  File "/app/app/main.py", line 9, in <module>
    from app.api import auth, dashboard, config, backup, archives, restore, schedule, logs, settings, health, events, repositories, ssh_keys
  File "/app/app/api/dashboard.py", line 11, in <module>
    from app.database.models import User, BackupJob, ScheduledJob, SystemLog
ImportError: cannot import name 'ScheduledJob' from 'app.database.models' (/app/app/database/models.py)
[2025-08-10 16:23:03 +0530] [12] [INFO] Worker exiting (pid: 12)
[2025-08-10 16:23:04 +0530] [13] [ERROR] Exception in worker process
Traceback (most recent call last):
  File "/usr/local/lib/python3.9/site-packages/gunicorn/arbiter.py", line 609, in spawn_worker
    worker.init_process()
  File "/usr/local/lib/python3.9/site-packages/uvicorn/workers.py", line 66, in init_process
    super(UvicornWorker, self).init_process()
  File "/usr/local/lib/python3.9/site-packages/gunicorn/workers/base.py", line 134, in init_process
    self.load_wsgi()
  File "/usr/local/lib/python3.9/site-packages/gunicorn/workers/base.py", line 146, in load_wsgi
    self.wsgi = self.app.wsgi()
  File "/usr/local/lib/python3.9/site-packages/gunicorn/app/base.py", line 67, in wsgi
    self.callable = self.load()
  File "/usr/local/lib/python3.9/site-packages/gunicorn/app/wsgiapp.py", line 58, in load
    return self.load_wsgiapp()
  File "/usr/local/lib/python3.9/site-packages/gunicorn/app/wsgiapp.py", line 48, in load_wsgiapp
    return util.import_app(self.app_uri)
  File "/usr/local/lib/python3.9/site-packages/gunicorn/util.py", line 371, in import_app
    mod = importlib.import_module(module)
  File "/usr/local/lib/python3.9/importlib/__init__.py", line 127, in import_module
    return _bootstrap._gcd_import(name[level:], package, level)
  File "<frozen importlib._bootstrap>", line 1030, in _gcd_import
  File "<frozen importlib._bootstrap>", line 1007, in _find_and_load
  File "<frozen importlib._bootstrap>", line 986, in _find_and_load_unlocked
  File "<frozen importlib._bootstrap>", line 680, in _load_unlocked
  File "<frozen importlib._bootstrap_external>", line 850, in exec_module
  File "<frozen importlib._bootstrap>", line 228, in _call_with_frames_removed
  File "/app/app/main.py", line 9, in <module>
    from app.api import auth, dashboard, config, backup, archives, restore, schedule, logs, settings, health, events, repositories, ssh_keys
  File "/app/app/api/dashboard.py", line 11, in <module>
    from app.database.models import User, BackupJob, ScheduledJob, SystemLog
ImportError: cannot import name 'ScheduledJob' from 'app.database.models' (/app/app/database/models.py)
[2025-08-10 16:23:04 +0530] [13] [INFO] Worker exiting (pid: 13)
[2025-08-10 16:23:04 +0530] [1] [ERROR] Worker (pid:12) exited with code 3
[2025-08-10 16:23:04 +0530] [1] [ERROR] Worker (pid:13) was sent SIGTERM!
[2025-08-10 16:23:04 +0530] [1] [ERROR] Shutting down: Master
[2025-08-10 16:23:04 +0530] [1] [ERROR] Reason: Worker failed to boot.
[2025-08-10 16:23:04 +0530] [1] [INFO] Starting gunicorn 21.2.0
[2025-08-10 16:23:04 +0530] [1] [INFO] Listening at: http://0.0.0.0:8000 (1)
[2025-08-10 16:23:04 +0530] [1] [INFO] Using worker: uvicorn.workers.UvicornWorker
[2025-08-10 16:23:04 +0530] [12] [INFO] Booting worker with pid: 12
[2025-08-10 16:23:05 +0530] [13] [INFO] Booting worker with pid: 13
[2025-08-10 16:23:05 +0530] [12] [ERROR] Exception in worker process
Traceback (most recent call last):
  File "/usr/local/lib/python3.9/site-packages/gunicorn/arbiter.py", line 609, in spawn_worker
    worker.init_process()
  File "/usr/local/lib/python3.9/site-packages/uvicorn/workers.py", line 66, in init_process
    super(UvicornWorker, self).init_process()
  File "/usr/local/lib/python3.9/site-packages/gunicorn/workers/base.py", line 134, in init_process
    self.load_wsgi()
  File "/usr/local/lib/python3.9/site-packages/gunicorn/workers/base.py", line 146, in load_wsgi
    self.wsgi = self.app.wsgi()
  File "/usr/local/lib/python3.9/site-packages/gunicorn/app/base.py", line 67, in wsgi
    self.callable = self.load()
  File "/usr/local/lib/python3.9/site-packages/gunicorn/app/wsgiapp.py", line 58, in load
    return self.load_wsgiapp()
  File "/usr/local/lib/python3.9/site-packages/gunicorn/app/wsgiapp.py", line 48, in load_wsgiapp
    return util.import_app(self.app_uri)
  File "/usr/local/lib/python3.9/site-packages/gunicorn/util.py", line 371, in import_app
    mod = importlib.import_module(module)
  File "/usr/local/lib/python3.9/importlib/__init__.py", line 127, in import_module
    return _bootstrap._gcd_import(name[level:], package, level)
  File "<frozen importlib._bootstrap>", line 1030, in _gcd_import
  File "<frozen importlib._bootstrap>", line 1007, in _find_and_load
  File "<frozen importlib._bootstrap>", line 986, in _find_and_load_unlocked
  File "<frozen importlib._bootstrap>", line 680, in _load_unlocked
  File "<frozen importlib._bootstrap_external>", line 850, in exec_module
  File "<frozen importlib._bootstrap>", line 228, in _call_with_frames_removed
  File "/app/app/main.py", line 9, in <module>
    from app.api import auth, dashboard, config, backup, archives, restore, schedule, logs, settings, health, events, repositories, ssh_keys
  File "/app/app/api/dashboard.py", line 11, in <module>
    from app.database.models import User, BackupJob, ScheduledJob, SystemLog
ImportError: cannot import name 'ScheduledJob' from 'app.database.models' (/app/app/database/models.py)
[2025-08-10 16:23:05 +0530] [12] [INFO] Worker exiting (pid: 12)
[2025-08-10 16:23:05 +0530] [1] [ERROR] Worker (pid:12) exited with code 3
[2025-08-10 16:23:05 +0530] [1] [ERROR] Worker (pid:13) was sent SIGTERM!
[2025-08-10 16:23:05 +0530] [1] [ERROR] Shutting down: Master
[2025-08-10 16:23:05 +0530] [1] [ERROR] Reason: Worker failed to boot.
[2025-08-10 16:23:06 +0530] [1] [INFO] Starting gunicorn 21.2.0
[2025-08-10 16:23:06 +0530] [1] [INFO] Listening at: http://0.0.0.0:8000 (1)
[2025-08-10 16:23:06 +0530] [1] [INFO] Using worker: uvicorn.workers.UvicornWorker
[2025-08-10 16:23:06 +0530] [12] [INFO] Booting worker with pid: 12
[2025-08-10 16:23:06 +0530] [13] [INFO] Booting worker with pid: 13
[2025-08-10 16:23:07 +0530] [12] [ERROR] Exception in worker process
Traceback (most recent call last):
  File "/usr/local/lib/python3.9/site-packages/gunicorn/arbiter.py", line 609, in spawn_worker
    worker.init_process()
  File "/usr/local/lib/python3.9/site-packages/uvicorn/workers.py", line 66, in init_process
    super(UvicornWorker, self).init_process()
  File "/usr/local/lib/python3.9/site-packages/gunicorn/workers/base.py", line 134, in init_process
    self.load_wsgi()
  File "/usr/local/lib/python3.9/site-packages/gunicorn/workers/base.py", line 146, in load_wsgi
    self.wsgi = self.app.wsgi()
  File "/usr/local/lib/python3.9/site-packages/gunicorn/app/base.py", line 67, in wsgi
    self.callable = self.load()
  File "/usr/local/lib/python3.9/site-packages/gunicorn/app/wsgiapp.py", line 58, in load
    return self.load_wsgiapp()
  File "/usr/local/lib/python3.9/site-packages/gunicorn/app/wsgiapp.py", line 48, in load_wsgiapp
    return util.import_app(self.app_uri)
  File "/usr/local/lib/python3.9/site-packages/gunicorn/util.py", line 371, in import_app
    mod = importlib.import_module(module)
  File "/usr/local/lib/python3.9/importlib/__init__.py", line 127, in import_module
    return _bootstrap._gcd_import(name[level:], package, level)
  File "<frozen importlib._bootstrap>", line 1030, in _gcd_import
  File "<frozen importlib._bootstrap>", line 1007, in _find_and_load
  File "<frozen importlib._bootstrap>", line 986, in _find_and_load_unlocked
  File "<frozen importlib._bootstrap>", line 680, in _load_unlocked
  File "<frozen importlib._bootstrap_external>", line 850, in exec_module
  File "<frozen importlib._bootstrap>", line 228, in _call_with_frames_removed
  File "/app/app/main.py", line 9, in <module>
    from app.api import auth, dashboard, config, backup, archives, restore, schedule, logs, settings, health, events, repositories, ssh_keys
  File "/app/app/api/dashboard.py", line 11, in <module>
    from app.database.models import User, BackupJob, ScheduledJob, SystemLog
ImportError: cannot import name 'ScheduledJob' from 'app.database.models' (/app/app/database/models.py)
[2025-08-10 16:23:07 +0530] [12] [INFO] Worker exiting (pid: 12)
[2025-08-10 16:23:07 +0530] [1] [ERROR] Worker (pid:12) exited with code 3
[2025-08-10 16:23:07 +0530] [1] [ERROR] Worker (pid:13) was sent SIGTERM!
[2025-08-10 16:23:07 +0530] [1] [ERROR] Shutting down: Master
[2025-08-10 16:23:07 +0530] [1] [ERROR] Reason: Worker failed to boot.
[2025-08-10 16:23:08 +0530] [1] [INFO] Starting gunicorn 21.2.0
[2025-08-10 16:23:08 +0530] [1] [INFO] Listening at: http://0.0.0.0:8000 (1)
[2025-08-10 16:23:08 +0530] [1] [INFO] Using worker: uvicorn.workers.UvicornWorker
[2025-08-10 16:23:08 +0530] [11] [INFO] Booting worker with pid: 11
[2025-08-10 16:23:09 +0530] [12] [INFO] Booting worker with pid: 12
[2025-08-10 16:23:09 +0530] [11] [ERROR] Exception in worker process
Traceback (most recent call last):
  File "/usr/local/lib/python3.9/site-packages/gunicorn/arbiter.py", line 609, in spawn_worker
    worker.init_process()
  File "/usr/local/lib/python3.9/site-packages/uvicorn/workers.py", line 66, in init_process
    super(UvicornWorker, self).init_process()
  File "/usr/local/lib/python3.9/site-packages/gunicorn/workers/base.py", line 134, in init_process
    self.load_wsgi()
  File "/usr/local/lib/python3.9/site-packages/gunicorn/workers/base.py", line 146, in load_wsgi
    self.wsgi = self.app.wsgi()
  File "/usr/local/lib/python3.9/site-packages/gunicorn/app/base.py", line 67, in wsgi
    self.callable = self.load()
  File "/usr/local/lib/python3.9/site-packages/gunicorn/app/wsgiapp.py", line 58, in load
    return self.load_wsgiapp()
  File "/usr/local/lib/python3.9/site-packages/gunicorn/app/wsgiapp.py", line 48, in load_wsgiapp
    return util.import_app(self.app_uri)
  File "/usr/local/lib/python3.9/site-packages/gunicorn/util.py", line 371, in import_app
    mod = importlib.import_module(module)
  File "/usr/local/lib/python3.9/importlib/__init__.py", line 127, in import_module
    return _bootstrap._gcd_import(name[level:], package, level)
  File "<frozen importlib._bootstrap>", line 1030, in _gcd_import
  File "<frozen importlib._bootstrap>", line 1007, in _find_and_load
  File "<frozen importlib._bootstrap>", line 986, in _find_and_load_unlocked
  File "<frozen importlib._bootstrap>", line 680, in _load_unlocked
  File "<frozen importlib._bootstrap_external>", line 850, in exec_module
  File "<frozen importlib._bootstrap>", line 228, in _call_with_frames_removed
  File "/app/app/main.py", line 9, in <module>
    from app.api import auth, dashboard, config, backup, archives, restore, schedule, logs, settings, health, events, repositories, ssh_keys
  File "/app/app/api/dashboard.py", line 11, in <module>
    from app.database.models import User, BackupJob, ScheduledJob, SystemLog
ImportError: cannot import name 'ScheduledJob' from 'app.database.models' (/app/app/database/models.py)
[2025-08-10 16:23:09 +0530] [11] [INFO] Worker exiting (pid: 11)
[2025-08-10 16:23:09 +0530] [1] [ERROR] Worker (pid:11) exited with code 3
[2025-08-10 16:23:09 +0530] [1] [ERROR] Worker (pid:12) was sent SIGTERM!
[2025-08-10 16:23:09 +0530] [1] [ERROR] Shutting down: Master
[2025-08-10 16:23:09 +0530] [1] [ERROR] Reason: Worker failed to boot.
[2025-08-10 16:23:11 +0530] [1] [INFO] Starting gunicorn 21.2.0
[2025-08-10 16:23:11 +0530] [1] [INFO] Listening at: http://0.0.0.0:8000 (1)
[2025-08-10 16:23:11 +0530] [1] [INFO] Using worker: uvicorn.workers.UvicornWorker
[2025-08-10 16:23:11 +0530] [12] [INFO] Booting worker with pid: 12
[2025-08-10 16:23:11 +0530] [13] [INFO] Booting worker with pid: 13
[2025-08-10 16:23:12 +0530] [12] [ERROR] Exception in worker process
Traceback (most recent call last):
  File "/usr/local/lib/python3.9/site-packages/gunicorn/arbiter.py", line 609, in spawn_worker
    worker.init_process()
  File "/usr/local/lib/python3.9/site-packages/uvicorn/workers.py", line 66, in init_process
    super(UvicornWorker, self).init_process()
  File "/usr/local/lib/python3.9/site-packages/gunicorn/workers/base.py", line 134, in init_process
    self.load_wsgi()
  File "/usr/local/lib/python3.9/site-packages/gunicorn/workers/base.py", line 146, in load_wsgi
    self.wsgi = self.app.wsgi()
  File "/usr/local/lib/python3.9/site-packages/gunicorn/app/base.py", line 67, in wsgi
    self.callable = self.load()
  File "/usr/local/lib/python3.9/site-packages/gunicorn/app/wsgiapp.py", line 58, in load
    return self.load_wsgiapp()
  File "/usr/local/lib/python3.9/site-packages/gunicorn/app/wsgiapp.py", line 48, in load_wsgiapp
    return util.import_app(self.app_uri)
  File "/usr/local/lib/python3.9/site-packages/gunicorn/util.py", line 371, in import_app
    mod = importlib.import_module(module)
  File "/usr/local/lib/python3.9/importlib/__init__.py", line 127, in import_module
    return _bootstrap._gcd_import(name[level:], package, level)
  File "<frozen importlib._bootstrap>", line 1030, in _gcd_import
  File "<frozen importlib._bootstrap>", line 1007, in _find_and_load
  File "<frozen importlib._bootstrap>", line 986, in _find_and_load_unlocked
  File "<frozen importlib._bootstrap>", line 680, in _load_unlocked
  File "<frozen importlib._bootstrap_external>", line 850, in exec_module
  File "<frozen importlib._bootstrap>", line 228, in _call_with_frames_removed
  File "/app/app/main.py", line 9, in <module>
    from app.api import auth, dashboard, config, backup, archives, restore, schedule, logs, settings, health, events, repositories, ssh_keys
  File "/app/app/api/dashboard.py", line 11, in <module>
    from app.database.models import User, BackupJob, ScheduledJob, SystemLog
ImportError: cannot import name 'ScheduledJob' from 'app.database.models' (/app/app/database/models.py)
[2025-08-10 16:23:12 +0530] [12] [INFO] Worker exiting (pid: 12)
[2025-08-10 16:23:12 +0530] [13] [ERROR] Exception in worker process
Traceback (most recent call last):
  File "/usr/local/lib/python3.9/site-packages/gunicorn/arbiter.py", line 609, in spawn_worker
    worker.init_process()
  File "/usr/local/lib/python3.9/site-packages/uvicorn/workers.py", line 66, in init_process
    super(UvicornWorker, self).init_process()
  File "/usr/local/lib/python3.9/site-packages/gunicorn/workers/base.py", line 134, in init_process
    self.load_wsgi()
  File "/usr/local/lib/python3.9/site-packages/gunicorn/workers/base.py", line 146, in load_wsgi
    self.wsgi = self.app.wsgi()
  File "/usr/local/lib/python3.9/site-packages/gunicorn/app/base.py", line 67, in wsgi
    self.callable = self.load()
  File "/usr/local/lib/python3.9/site-packages/gunicorn/app/wsgiapp.py", line 58, in load
    return self.load_wsgiapp()
  File "/usr/local/lib/python3.9/site-packages/gunicorn/app/wsgiapp.py", line 48, in load_wsgiapp
    return util.import_app(self.app_uri)
  File "/usr/local/lib/python3.9/site-packages/gunicorn/util.py", line 371, in import_app
    mod = importlib.import_module(module)
  File "/usr/local/lib/python3.9/importlib/__init__.py", line 127, in import_module
    return _bootstrap._gcd_import(name[level:], package, level)
  File "<frozen importlib._bootstrap>", line 1030, in _gcd_import
  File "<frozen importlib._bootstrap>", line 1007, in _find_and_load
  File "<frozen importlib._bootstrap>", line 986, in _find_and_load_unlocked
  File "<frozen importlib._bootstrap>", line 680, in _load_unlocked
  File "<frozen importlib._bootstrap_external>", line 850, in exec_module
  File "<frozen importlib._bootstrap>", line 228, in _call_with_frames_removed
  File "/app/app/main.py", line 9, in <module>
    from app.api import auth, dashboard, config, backup, archives, restore, schedule, logs, settings, health, events, repositories, ssh_keys
  File "/app/app/api/dashboard.py", line 11, in <module>
    from app.database.models import User, BackupJob, ScheduledJob, SystemLog
ImportError: cannot import name 'ScheduledJob' from 'app.database.models' (/app/app/database/models.py)
[2025-08-10 16:23:12 +0530] [13] [INFO] Worker exiting (pid: 13)
[2025-08-10 16:23:12 +0530] [1] [ERROR] Worker (pid:12) exited with code 3
[2025-08-10 16:23:12 +0530] [1] [ERROR] Worker (pid:13) was sent SIGTERM!
[2025-08-10 16:23:12 +0530] [1] [ERROR] Shutting down: Master
[2025-08-10 16:23:12 +0530] [1] [ERROR] Reason: Worker failed to boot.
[2025-08-10 16:23:16 +0530] [1] [INFO] Starting gunicorn 21.2.0
[2025-08-10 16:23:16 +0530] [1] [INFO] Listening at: http://0.0.0.0:8000 (1)
[2025-08-10 16:23:16 +0530] [1] [INFO] Using worker: uvicorn.workers.UvicornWorker
[2025-08-10 16:23:16 +0530] [12] [INFO] Booting worker with pid: 12
[2025-08-10 16:23:16 +0530] [13] [INFO] Booting worker with pid: 13
[2025-08-10 16:23:17 +0530] [12] [ERROR] Exception in worker process
Traceback (most recent call last):
  File "/usr/local/lib/python3.9/site-packages/gunicorn/arbiter.py", line 609, in spawn_worker
    worker.init_process()
  File "/usr/local/lib/python3.9/site-packages/uvicorn/workers.py", line 66, in init_process
    super(UvicornWorker, self).init_process()
  File "/usr/local/lib/python3.9/site-packages/gunicorn/workers/base.py", line 134, in init_process
    self.load_wsgi()
  File "/usr/local/lib/python3.9/site-packages/gunicorn/workers/base.py", line 146, in load_wsgi
    self.wsgi = self.app.wsgi()
  File "/usr/local/lib/python3.9/site-packages/gunicorn/app/base.py", line 67, in wsgi
    self.callable = self.load()
  File "/usr/local/lib/python3.9/site-packages/gunicorn/app/wsgiapp.py", line 58, in load
    return self.load_wsgiapp()
  File "/usr/local/lib/python3.9/site-packages/gunicorn/app/wsgiapp.py", line 48, in load_wsgiapp
    return util.import_app(self.app_uri)
  File "/usr/local/lib/python3.9/site-packages/gunicorn/util.py", line 371, in import_app
    mod = importlib.import_module(module)
  File "/usr/local/lib/python3.9/importlib/__init__.py", line 127, in import_module
    return _bootstrap._gcd_import(name[level:], package, level)
  File "<frozen importlib._bootstrap>", line 1030, in _gcd_import
  File "<frozen importlib._bootstrap>", line 1007, in _find_and_load
  File "<frozen importlib._bootstrap>", line 986, in _find_and_load_unlocked
  File "<frozen importlib._bootstrap>", line 680, in _load_unlocked
  File "<frozen importlib._bootstrap_external>", line 850, in exec_module
  File "<frozen importlib._bootstrap>", line 228, in _call_with_frames_removed
  File "/app/app/main.py", line 9, in <module>
    from app.api import auth, dashboard, config, backup, archives, restore, schedule, logs, settings, health, events, repositories, ssh_keys
  File "/app/app/api/dashboard.py", line 11, in <module>
    from app.database.models import User, BackupJob, ScheduledJob, SystemLog
ImportError: cannot import name 'ScheduledJob' from 'app.database.models' (/app/app/database/models.py)
[2025-08-10 16:23:17 +0530] [12] [INFO] Worker exiting (pid: 12)
[2025-08-10 16:23:17 +0530] [13] [ERROR] Exception in worker process
Traceback (most recent call last):
  File "/usr/local/lib/python3.9/site-packages/gunicorn/arbiter.py", line 609, in spawn_worker
    worker.init_process()
  File "/usr/local/lib/python3.9/site-packages/uvicorn/workers.py", line 66, in init_process
    super(UvicornWorker, self).init_process()
  File "/usr/local/lib/python3.9/site-packages/gunicorn/workers/base.py", line 134, in init_process
    self.load_wsgi()
  File "/usr/local/lib/python3.9/site-packages/gunicorn/workers/base.py", line 146, in load_wsgi
    self.wsgi = self.app.wsgi()
  File "/usr/local/lib/python3.9/site-packages/gunicorn/app/base.py", line 67, in wsgi
    self.callable = self.load()
  File "/usr/local/lib/python3.9/site-packages/gunicorn/app/wsgiapp.py", line 58, in load
    return self.load_wsgiapp()
  File "/usr/local/lib/python3.9/site-packages/gunicorn/app/wsgiapp.py", line 48, in load_wsgiapp
    return util.import_app(self.app_uri)
  File "/usr/local/lib/python3.9/site-packages/gunicorn/util.py", line 371, in import_app
    mod = importlib.import_module(module)
  File "/usr/local/lib/python3.9/importlib/__init__.py", line 127, in import_module
    return _bootstrap._gcd_import(name[level:], package, level)
  File "<frozen importlib._bootstrap>", line 1030, in _gcd_import
  File "<frozen importlib._bootstrap>", line 1007, in _find_and_load
  File "<frozen importlib._bootstrap>", line 986, in _find_and_load_unlocked
  File "<frozen importlib._bootstrap>", line 680, in _load_unlocked
  File "<frozen importlib._bootstrap_external>", line 850, in exec_module
  File "<frozen importlib._bootstrap>", line 228, in _call_with_frames_removed
  File "/app/app/main.py", line 9, in <module>
    from app.api import auth, dashboard, config, backup, archives, restore, schedule, logs, settings, health, events, repositories, ssh_keys
  File "/app/app/api/dashboard.py", line 11, in <module>
    from app.database.models import User, BackupJob, ScheduledJob, SystemLog
ImportError: cannot import name 'ScheduledJob' from 'app.database.models' (/app/app/database/models.py)
[2025-08-10 16:23:17 +0530] [13] [INFO] Worker exiting (pid: 13)
[2025-08-10 16:23:17 +0530] [1] [ERROR] Worker (pid:12) exited with code 3
[2025-08-10 16:23:17 +0530] [1] [ERROR] Worker (pid:13) was sent SIGTERM!
[2025-08-10 16:23:17 +0530] [1] [ERROR] Shutting down: Master
[2025-08-10 16:23:17 +0530] [1] [ERROR] Reason: Worker failed to boot.
[2025-08-10 16:23:24 +0530] [1] [INFO] Starting gunicorn 21.2.0
[2025-08-10 16:23:24 +0530] [1] [INFO] Listening at: http://0.0.0.0:8000 (1)
[2025-08-10 16:23:24 +0530] [1] [INFO] Using worker: uvicorn.workers.UvicornWorker
[2025-08-10 16:23:24 +0530] [12] [INFO] Booting worker with pid: 12
[2025-08-10 16:23:24 +0530] [13] [INFO] Booting worker with pid: 13
[2025-08-10 16:23:24 +0530] [12] [ERROR] Exception in worker process
Traceback (most recent call last):
  File "/usr/local/lib/python3.9/site-packages/gunicorn/arbiter.py", line 609, in spawn_worker
    worker.init_process()
  File "/usr/local/lib/python3.9/site-packages/uvicorn/workers.py", line 66, in init_process
    super(UvicornWorker, self).init_process()
  File "/usr/local/lib/python3.9/site-packages/gunicorn/workers/base.py", line 134, in init_process
    self.load_wsgi()
  File "/usr/local/lib/python3.9/site-packages/gunicorn/workers/base.py", line 146, in load_wsgi
    self.wsgi = self.app.wsgi()
  File "/usr/local/lib/python3.9/site-packages/gunicorn/app/base.py", line 67, in wsgi
    self.callable = self.load()
  File "/usr/local/lib/python3.9/site-packages/gunicorn/app/wsgiapp.py", line 58, in load
    return self.load_wsgiapp()
  File "/usr/local/lib/python3.9/site-packages/gunicorn/app/wsgiapp.py", line 48, in load_wsgiapp
    return util.import_app(self.app_uri)
  File "/usr/local/lib/python3.9/site-packages/gunicorn/util.py", line 371, in import_app
    mod = importlib.import_module(module)
  File "/usr/local/lib/python3.9/importlib/__init__.py", line 127, in import_module
    return _bootstrap._gcd_import(name[level:], package, level)
  File "<frozen importlib._bootstrap>", line 1030, in _gcd_import
  File "<frozen importlib._bootstrap>", line 1007, in _find_and_load
  File "<frozen importlib._bootstrap>", line 986, in _find_and_load_unlocked
  File "<frozen importlib._bootstrap>", line 680, in _load_unlocked
  File "<frozen importlib._bootstrap_external>", line 850, in exec_module
  File "<frozen importlib._bootstrap>", line 228, in _call_with_frames_removed
  File "/app/app/main.py", line 9, in <module>
    from app.api import auth, dashboard, config, backup, archives, restore, schedule, logs, settings, health, events, repositories, ssh_keys
  File "/app/app/api/dashboard.py", line 11, in <module>
    from app.database.models import User, BackupJob, ScheduledJob, SystemLog
ImportError: cannot import name 'ScheduledJob' from 'app.database.models' (/app/app/database/models.py)
[2025-08-10 16:23:24 +0530] [12] [INFO] Worker exiting (pid: 12)
[2025-08-10 16:23:25 +0530] [13] [ERROR] Exception in worker process
Traceback (most recent call last):
  File "/usr/local/lib/python3.9/site-packages/gunicorn/arbiter.py", line 609, in spawn_worker
    worker.init_process()
  File "/usr/local/lib/python3.9/site-packages/uvicorn/workers.py", line 66, in init_process
    super(UvicornWorker, self).init_process()
  File "/usr/local/lib/python3.9/site-packages/gunicorn/workers/base.py", line 134, in init_process
    self.load_wsgi()
  File "/usr/local/lib/python3.9/site-packages/gunicorn/workers/base.py", line 146, in load_wsgi
    self.wsgi = self.app.wsgi()
  File "/usr/local/lib/python3.9/site-packages/gunicorn/app/base.py", line 67, in wsgi
    self.callable = self.load()
  File "/usr/local/lib/python3.9/site-packages/gunicorn/app/wsgiapp.py", line 58, in load
    return self.load_wsgiapp()
  File "/usr/local/lib/python3.9/site-packages/gunicorn/app/wsgiapp.py", line 48, in load_wsgiapp
    return util.import_app(self.app_uri)
  File "/usr/local/lib/python3.9/site-packages/gunicorn/util.py", line 371, in import_app
    mod = importlib.import_module(module)
  File "/usr/local/lib/python3.9/importlib/__init__.py", line 127, in import_module
    return _bootstrap._gcd_import(name[level:], package, level)
  File "<frozen importlib._bootstrap>", line 1030, in _gcd_import
  File "<frozen importlib._bootstrap>", line 1007, in _find_and_load
  File "<frozen importlib._bootstrap>", line 986, in _find_and_load_unlocked
  File "<frozen importlib._bootstrap>", line 680, in _load_unlocked
  File "<frozen importlib._bootstrap_external>", line 850, in exec_module
  File "<frozen importlib._bootstrap>", line 228, in _call_with_frames_removed
  File "/app/app/main.py", line 9, in <module>
    from app.api import auth, dashboard, config, backup, archives, restore, schedule, logs, settings, health, events, repositories, ssh_keys
  File "/app/app/api/dashboard.py", line 11, in <module>
    from app.database.models import User, BackupJob, ScheduledJob, SystemLog
ImportError: cannot import name 'ScheduledJob' from 'app.database.models' (/app/app/database/models.py)
[2025-08-10 16:23:25 +0530] [13] [INFO] Worker exiting (pid: 13)
[2025-08-10 16:23:25 +0530] [1] [ERROR] Worker (pid:12) exited with code 3
[2025-08-10 16:23:25 +0530] [1] [ERROR] Worker (pid:13) was sent SIGTERM!
[2025-08-10 16:23:25 +0530] [1] [ERROR] Shutting down: Master
[2025-08-10 16:23:25 +0530] [1] [ERROR] Reason: Worker failed to boot.
[2025-08-10 16:23:54 +0530] [1] [INFO] Starting gunicorn 21.2.0
[2025-08-10 16:23:54 +0530] [1] [INFO] Listening at: http://0.0.0.0:8000 (1)
[2025-08-10 16:23:54 +0530] [1] [INFO] Using worker: uvicorn.workers.UvicornWorker
[2025-08-10 16:23:54 +0530] [12] [INFO] Booting worker with pid: 12
[2025-08-10 16:23:54 +0530] [13] [INFO] Booting worker with pid: 13
[2025-08-10 16:23:55 +0530] [13] [ERROR] Exception in worker process
Traceback (most recent call last):
  File "/usr/local/lib/python3.9/site-packages/gunicorn/arbiter.py", line 609, in spawn_worker
    worker.init_process()
  File "/usr/local/lib/python3.9/site-packages/uvicorn/workers.py", line 66, in init_process
    super(UvicornWorker, self).init_process()
  File "/usr/local/lib/python3.9/site-packages/gunicorn/workers/base.py", line 134, in init_process
    self.load_wsgi()
  File "/usr/local/lib/python3.9/site-packages/gunicorn/workers/base.py", line 146, in load_wsgi
    self.wsgi = self.app.wsgi()
  File "/usr/local/lib/python3.9/site-packages/gunicorn/app/base.py", line 67, in wsgi
    self.callable = self.load()
  File "/usr/local/lib/python3.9/site-packages/gunicorn/app/wsgiapp.py", line 58, in load
    return self.load_wsgiapp()
  File "/usr/local/lib/python3.9/site-packages/gunicorn/app/wsgiapp.py", line 48, in load_wsgiapp
    return util.import_app(self.app_uri)
  File "/usr/local/lib/python3.9/site-packages/gunicorn/util.py", line 371, in import_app
    mod = importlib.import_module(module)
  File "/usr/local/lib/python3.9/importlib/__init__.py", line 127, in import_module
    return _bootstrap._gcd_import(name[level:], package, level)
  File "<frozen importlib._bootstrap>", line 1030, in _gcd_import
  File "<frozen importlib._bootstrap>", line 1007, in _find_and_load
  File "<frozen importlib._bootstrap>", line 986, in _find_and_load_unlocked
  File "<frozen importlib._bootstrap>", line 680, in _load_unlocked
  File "<frozen importlib._bootstrap_external>", line 850, in exec_module
  File "<frozen importlib._bootstrap>", line 228, in _call_with_frames_removed
  File "/app/app/main.py", line 9, in <module>
    from app.api import auth, dashboard, config, backup, archives, restore, schedule, logs, settings, health, events, repositories, ssh_keys
  File "/app/app/api/dashboard.py", line 11, in <module>
    from app.database.models import User, BackupJob, ScheduledJob, SystemLog
ImportError: cannot import name 'ScheduledJob' from 'app.database.models' (/app/app/database/models.py)
[2025-08-10 16:23:55 +0530] [13] [INFO] Worker exiting (pid: 13)
[2025-08-10 16:23:55 +0530] [12] [ERROR] Exception in worker process
Traceback (most recent call last):
  File "/usr/local/lib/python3.9/site-packages/gunicorn/arbiter.py", line 609, in spawn_worker
    worker.init_process()
  File "/usr/local/lib/python3.9/site-packages/uvicorn/workers.py", line 66, in init_process
    super(UvicornWorker, self).init_process()
  File "/usr/local/lib/python3.9/site-packages/gunicorn/workers/base.py", line 134, in init_process
    self.load_wsgi()
  File "/usr/local/lib/python3.9/site-packages/gunicorn/workers/base.py", line 146, in load_wsgi
    self.wsgi = self.app.wsgi()
  File "/usr/local/lib/python3.9/site-packages/gunicorn/app/base.py", line 67, in wsgi
    self.callable = self.load()
  File "/usr/local/lib/python3.9/site-packages/gunicorn/app/wsgiapp.py", line 58, in load
    return self.load_wsgiapp()
  File "/usr/local/lib/python3.9/site-packages/gunicorn/app/wsgiapp.py", line 48, in load_wsgiapp
    return util.import_app(self.app_uri)
  File "/usr/local/lib/python3.9/site-packages/gunicorn/util.py", line 371, in import_app
    mod = importlib.import_module(module)
  File "/usr/local/lib/python3.9/importlib/__init__.py", line 127, in import_module
    return _bootstrap._gcd_import(name[level:], package, level)
  File "<frozen importlib._bootstrap>", line 1030, in _gcd_import
  File "<frozen importlib._bootstrap>", line 1007, in _find_and_load
  File "<frozen importlib._bootstrap>", line 986, in _find_and_load_unlocked
  File "<frozen importlib._bootstrap>", line 680, in _load_unlocked
  File "<frozen importlib._bootstrap_external>", line 850, in exec_module
  File "<frozen importlib._bootstrap>", line 228, in _call_with_frames_removed
  File "/app/app/main.py", line 9, in <module>
    from app.api import auth, dashboard, config, backup, archives, restore, schedule, logs, settings, health, events, repositories, ssh_keys
  File "/app/app/api/dashboard.py", line 11, in <module>
    from app.database.models import User, BackupJob, ScheduledJob, SystemLog
ImportError: cannot import name 'ScheduledJob' from 'app.database.models' (/app/app/database/models.py)
[2025-08-10 16:23:55 +0530] [12] [INFO] Worker exiting (pid: 12)
[2025-08-10 16:23:55 +0530] [1] [ERROR] Worker (pid:13) exited with code 3
[2025-08-10 16:23:55 +0530] [1] [ERROR] Worker (pid:12) was sent SIGTERM!
[2025-08-10 16:23:55 +0530] [1] [ERROR] Shutting down: Master
[2025-08-10 16:23:55 +0530] [1] [ERROR] Reason: Worker failed to boot.
[2025-08-10 16:23:56 +0530] [1] [INFO] Starting gunicorn 21.2.0
[2025-08-10 16:23:56 +0530] [1] [INFO] Listening at: http://0.0.0.0:8000 (1)
[2025-08-10 16:23:56 +0530] [1] [INFO] Using worker: uvicorn.workers.UvicornWorker
[2025-08-10 16:23:56 +0530] [12] [INFO] Booting worker with pid: 12
[2025-08-10 16:23:56 +0530] [13] [INFO] Booting worker with pid: 13
[2025-08-10 16:23:56 +0530] [12] [ERROR] Exception in worker process
Traceback (most recent call last):
  File "/usr/local/lib/python3.9/site-packages/gunicorn/arbiter.py", line 609, in spawn_worker
    worker.init_process()
  File "/usr/local/lib/python3.9/site-packages/uvicorn/workers.py", line 66, in init_process
    super(UvicornWorker, self).init_process()
  File "/usr/local/lib/python3.9/site-packages/gunicorn/workers/base.py", line 134, in init_process
    self.load_wsgi()
  File "/usr/local/lib/python3.9/site-packages/gunicorn/workers/base.py", line 146, in load_wsgi
    self.wsgi = self.app.wsgi()
  File "/usr/local/lib/python3.9/site-packages/gunicorn/app/base.py", line 67, in wsgi
    self.callable = self.load()
  File "/usr/local/lib/python3.9/site-packages/gunicorn/app/wsgiapp.py", line 58, in load
    return self.load_wsgiapp()
  File "/usr/local/lib/python3.9/site-packages/gunicorn/app/wsgiapp.py", line 48, in load_wsgiapp
    return util.import_app(self.app_uri)
  File "/usr/local/lib/python3.9/site-packages/gunicorn/util.py", line 371, in import_app
    mod = importlib.import_module(module)
  File "/usr/local/lib/python3.9/importlib/__init__.py", line 127, in import_module
    return _bootstrap._gcd_import(name[level:], package, level)
  File "<frozen importlib._bootstrap>", line 1030, in _gcd_import
  File "<frozen importlib._bootstrap>", line 1007, in _find_and_load
  File "<frozen importlib._bootstrap>", line 986, in _find_and_load_unlocked
  File "<frozen importlib._bootstrap>", line 680, in _load_unlocked
  File "<frozen importlib._bootstrap_external>", line 850, in exec_module
  File "<frozen importlib._bootstrap>", line 228, in _call_with_frames_removed
  File "/app/app/main.py", line 9, in <module>
    from app.api import auth, dashboard, config, backup, archives, restore, schedule, logs, settings, health, events, repositories, ssh_keys
  File "/app/app/api/dashboard.py", line 11, in <module>
    from app.database.models import User, BackupJob, ScheduledJob, SystemLog
ImportError: cannot import name 'ScheduledJob' from 'app.database.models' (/app/app/database/models.py)
[2025-08-10 16:23:56 +0530] [12] [INFO] Worker exiting (pid: 12)
[2025-08-10 16:23:56 +0530] [1] [ERROR] Worker (pid:12) exited with code 3
[2025-08-10 16:23:56 +0530] [1] [ERROR] Worker (pid:13) was sent SIGTERM!
[2025-08-10 16:23:57 +0530] [1] [ERROR] Shutting down: Master
[2025-08-10 16:23:57 +0530] [1] [ERROR] Reason: Worker failed to boot.
[2025-08-10 16:23:57 +0530] [1] [INFO] Starting gunicorn 21.2.0
[2025-08-10 16:23:57 +0530] [1] [INFO] Listening at: http://0.0.0.0:8000 (1)
[2025-08-10 16:23:57 +0530] [1] [INFO] Using worker: uvicorn.workers.UvicornWorker
[2025-08-10 16:23:57 +0530] [12] [INFO] Booting worker with pid: 12
[2025-08-10 16:23:57 +0530] [13] [INFO] Booting worker with pid: 13
[2025-08-10 16:23:58 +0530] [12] [ERROR] Exception in worker process
Traceback (most recent call last):
  File "/usr/local/lib/python3.9/site-packages/gunicorn/arbiter.py", line 609, in spawn_worker
    worker.init_process()
  File "/usr/local/lib/python3.9/site-packages/uvicorn/workers.py", line 66, in init_process
    super(UvicornWorker, self).init_process()
  File "/usr/local/lib/python3.9/site-packages/gunicorn/workers/base.py", line 134, in init_process
    self.load_wsgi()
  File "/usr/local/lib/python3.9/site-packages/gunicorn/workers/base.py", line 146, in load_wsgi
    self.wsgi = self.app.wsgi()
  File "/usr/local/lib/python3.9/site-packages/gunicorn/app/base.py", line 67, in wsgi
    self.callable = self.load()
  File "/usr/local/lib/python3.9/site-packages/gunicorn/app/wsgiapp.py", line 58, in load
    return self.load_wsgiapp()
  File "/usr/local/lib/python3.9/site-packages/gunicorn/app/wsgiapp.py", line 48, in load_wsgiapp
    return util.import_app(self.app_uri)
  File "/usr/local/lib/python3.9/site-packages/gunicorn/util.py", line 371, in import_app
    mod = importlib.import_module(module)
  File "/usr/local/lib/python3.9/importlib/__init__.py", line 127, in import_module
    return _bootstrap._gcd_import(name[level:], package, level)
  File "<frozen importlib._bootstrap>", line 1030, in _gcd_import
  File "<frozen importlib._bootstrap>", line 1007, in _find_and_load
  File "<frozen importlib._bootstrap>", line 986, in _find_and_load_unlocked
  File "<frozen importlib._bootstrap>", line 680, in _load_unlocked
  File "<frozen importlib._bootstrap_external>", line 850, in exec_module
  File "<frozen importlib._bootstrap>", line 228, in _call_with_frames_removed
  File "/app/app/main.py", line 9, in <module>
    from app.api import auth, dashboard, config, backup, archives, restore, schedule, logs, settings, health, events, repositories, ssh_keys
  File "/app/app/api/dashboard.py", line 11, in <module>
    from app.database.models import User, BackupJob, ScheduledJob, SystemLog
ImportError: cannot import name 'ScheduledJob' from 'app.database.models' (/app/app/database/models.py)
[2025-08-10 16:23:58 +0530] [12] [INFO] Worker exiting (pid: 12)
[2025-08-10 16:23:58 +0530] [13] [ERROR] Exception in worker process
Traceback (most recent call last):
  File "/usr/local/lib/python3.9/site-packages/gunicorn/arbiter.py", line 609, in spawn_worker
    worker.init_process()
  File "/usr/local/lib/python3.9/site-packages/uvicorn/workers.py", line 66, in init_process
    super(UvicornWorker, self).init_process()
  File "/usr/local/lib/python3.9/site-packages/gunicorn/workers/base.py", line 134, in init_process
    self.load_wsgi()
  File "/usr/local/lib/python3.9/site-packages/gunicorn/workers/base.py", line 146, in load_wsgi
    self.wsgi = self.app.wsgi()
  File "/usr/local/lib/python3.9/site-packages/gunicorn/app/base.py", line 67, in wsgi
    self.callable = self.load()
  File "/usr/local/lib/python3.9/site-packages/gunicorn/app/wsgiapp.py", line 58, in load
    return self.load_wsgiapp()
  File "/usr/local/lib/python3.9/site-packages/gunicorn/app/wsgiapp.py", line 48, in load_wsgiapp
    return util.import_app(self.app_uri)
  File "/usr/local/lib/python3.9/site-packages/gunicorn/util.py", line 371, in import_app
    mod = importlib.import_module(module)
  File "/usr/local/lib/python3.9/importlib/__init__.py", line 127, in import_module
    return _bootstrap._gcd_import(name[level:], package, level)
  File "<frozen importlib._bootstrap>", line 1030, in _gcd_import
  File "<frozen importlib._bootstrap>", line 1007, in _find_and_load
  File "<frozen importlib._bootstrap>", line 986, in _find_and_load_unlocked
  File "<frozen importlib._bootstrap>", line 680, in _load_unlocked
  File "<frozen importlib._bootstrap_external>", line 850, in exec_module
  File "<frozen importlib._bootstrap>", line 228, in _call_with_frames_removed
  File "/app/app/main.py", line 9, in <module>
    from app.api import auth, dashboard, config, backup, archives, restore, schedule, logs, settings, health, events, repositories, ssh_keys
  File "/app/app/api/dashboard.py", line 11, in <module>
    from app.database.models import User, BackupJob, ScheduledJob, SystemLog
ImportError: cannot import name 'ScheduledJob' from 'app.database.models' (/app/app/database/models.py)
[2025-08-10 16:23:58 +0530] [13] [INFO] Worker exiting (pid: 13)
[2025-08-10 16:23:58 +0530] [1] [ERROR] Worker (pid:12) exited with code 3
[2025-08-10 16:23:58 +0530] [1] [ERROR] Worker (pid:13) was sent SIGTERM!
[2025-08-10 16:23:58 +0530] [1] [ERROR] Shutting down: Master
[2025-08-10 16:23:58 +0530] [1] [ERROR] Reason: Worker failed to boot.
[2025-08-10 16:23:59 +0530] [1] [INFO] Starting gunicorn 21.2.0
[2025-08-10 16:23:59 +0530] [1] [INFO] Listening at: http://0.0.0.0:8000 (1)
[2025-08-10 16:23:59 +0530] [1] [INFO] Using worker: uvicorn.workers.UvicornWorker
[2025-08-10 16:23:59 +0530] [11] [INFO] Booting worker with pid: 11
[2025-08-10 16:23:59 +0530] [12] [INFO] Booting worker with pid: 12
[2025-08-10 16:24:00 +0530] [11] [ERROR] Exception in worker process
Traceback (most recent call last):
  File "/usr/local/lib/python3.9/site-packages/gunicorn/arbiter.py", line 609, in spawn_worker
    worker.init_process()
  File "/usr/local/lib/python3.9/site-packages/uvicorn/workers.py", line 66, in init_process
    super(UvicornWorker, self).init_process()
  File "/usr/local/lib/python3.9/site-packages/gunicorn/workers/base.py", line 134, in init_process
    self.load_wsgi()
  File "/usr/local/lib/python3.9/site-packages/gunicorn/workers/base.py", line 146, in load_wsgi
    self.wsgi = self.app.wsgi()
  File "/usr/local/lib/python3.9/site-packages/gunicorn/app/base.py", line 67, in wsgi
    self.callable = self.load()
  File "/usr/local/lib/python3.9/site-packages/gunicorn/app/wsgiapp.py", line 58, in load
    return self.load_wsgiapp()
  File "/usr/local/lib/python3.9/site-packages/gunicorn/app/wsgiapp.py", line 48, in load_wsgiapp
    return util.import_app(self.app_uri)
  File "/usr/local/lib/python3.9/site-packages/gunicorn/util.py", line 371, in import_app
    mod = importlib.import_module(module)
  File "/usr/local/lib/python3.9/importlib/__init__.py", line 127, in import_module
    return _bootstrap._gcd_import(name[level:], package, level)
  File "<frozen importlib._bootstrap>", line 1030, in _gcd_import
  File "<frozen importlib._bootstrap>", line 1007, in _find_and_load
  File "<frozen importlib._bootstrap>", line 986, in _find_and_load_unlocked
  File "<frozen importlib._bootstrap>", line 680, in _load_unlocked
  File "<frozen importlib._bootstrap_external>", line 850, in exec_module
  File "<frozen importlib._bootstrap>", line 228, in _call_with_frames_removed
  File "/app/app/main.py", line 9, in <module>
    from app.api import auth, dashboard, config, backup, archives, restore, schedule, logs, settings, health, events, repositories, ssh_keys
  File "/app/app/api/dashboard.py", line 11, in <module>
    from app.database.models import User, BackupJob, ScheduledJob, SystemLog
ImportError: cannot import name 'ScheduledJob' from 'app.database.models' (/app/app/database/models.py)
[2025-08-10 16:24:00 +0530] [11] [INFO] Worker exiting (pid: 11)
[2025-08-10 16:24:00 +0530] [1] [ERROR] Worker (pid:11) exited with code 3
[2025-08-10 16:24:00 +0530] [1] [ERROR] Worker (pid:12) was sent SIGTERM!
[2025-08-10 16:24:00 +0530] [1] [ERROR] Shutting down: Master
[2025-08-10 16:24:00 +0530] [1] [ERROR] Reason: Worker failed to boot.
[2025-08-10 16:24:01 +0530] [1] [INFO] Starting gunicorn 21.2.0
[2025-08-10 16:24:01 +0530] [1] [INFO] Listening at: http://0.0.0.0:8000 (1)
[2025-08-10 16:24:01 +0530] [1] [INFO] Using worker: uvicorn.workers.UvicornWorker
[2025-08-10 16:24:01 +0530] [11] [INFO] Booting worker with pid: 11
[2025-08-10 16:24:01 +0530] [12] [INFO] Booting worker with pid: 12
[2025-08-10 16:24:02 +0530] [11] [ERROR] Exception in worker process
Traceback (most recent call last):
  File "/usr/local/lib/python3.9/site-packages/gunicorn/arbiter.py", line 609, in spawn_worker
    worker.init_process()
  File "/usr/local/lib/python3.9/site-packages/uvicorn/workers.py", line 66, in init_process
    super(UvicornWorker, self).init_process()
  File "/usr/local/lib/python3.9/site-packages/gunicorn/workers/base.py", line 134, in init_process
    self.load_wsgi()
  File "/usr/local/lib/python3.9/site-packages/gunicorn/workers/base.py", line 146, in load_wsgi
    self.wsgi = self.app.wsgi()
  File "/usr/local/lib/python3.9/site-packages/gunicorn/app/base.py", line 67, in wsgi
    self.callable = self.load()
  File "/usr/local/lib/python3.9/site-packages/gunicorn/app/wsgiapp.py", line 58, in load
    return self.load_wsgiapp()
  File "/usr/local/lib/python3.9/site-packages/gunicorn/app/wsgiapp.py", line 48, in load_wsgiapp
    return util.import_app(self.app_uri)
  File "/usr/local/lib/python3.9/site-packages/gunicorn/util.py", line 371, in import_app
    mod = importlib.import_module(module)
  File "/usr/local/lib/python3.9/importlib/__init__.py", line 127, in import_module
    return _bootstrap._gcd_import(name[level:], package, level)
  File "<frozen importlib._bootstrap>", line 1030, in _gcd_import
  File "<frozen importlib._bootstrap>", line 1007, in _find_and_load
  File "<frozen importlib._bootstrap>", line 986, in _find_and_load_unlocked
  File "<frozen importlib._bootstrap>", line 680, in _load_unlocked
  File "<frozen importlib._bootstrap_external>", line 850, in exec_module
  File "<frozen importlib._bootstrap>", line 228, in _call_with_frames_removed
  File "/app/app/main.py", line 9, in <module>
    from app.api import auth, dashboard, config, backup, archives, restore, schedule, logs, settings, health, events, repositories, ssh_keys
  File "/app/app/api/dashboard.py", line 11, in <module>
    from app.database.models import User, BackupJob, ScheduledJob, SystemLog
ImportError: cannot import name 'ScheduledJob' from 'app.database.models' (/app/app/database/models.py)
[2025-08-10 16:24:02 +0530] [11] [INFO] Worker exiting (pid: 11)
[2025-08-10 16:24:02 +0530] [1] [ERROR] Worker (pid:11) exited with code 3
[2025-08-10 16:24:02 +0530] [1] [ERROR] Worker (pid:12) was sent SIGTERM!
[2025-08-10 16:24:02 +0530] [1] [ERROR] Shutting down: Master
[2025-08-10 16:24:02 +0530] [1] [ERROR] Reason: Worker failed to boot.
[2025-08-10 16:24:05 +0530] [1] [INFO] Starting gunicorn 21.2.0
[2025-08-10 16:24:05 +0530] [1] [INFO] Listening at: http://0.0.0.0:8000 (1)
[2025-08-10 16:24:05 +0530] [1] [INFO] Using worker: uvicorn.workers.UvicornWorker
[2025-08-10 16:24:05 +0530] [12] [INFO] Booting worker with pid: 12
[2025-08-10 16:24:05 +0530] [13] [INFO] Booting worker with pid: 13
[2025-08-10 16:24:05 +0530] [13] [ERROR] Exception in worker process
Traceback (most recent call last):
  File "/usr/local/lib/python3.9/site-packages/gunicorn/arbiter.py", line 609, in spawn_worker
    worker.init_process()
  File "/usr/local/lib/python3.9/site-packages/uvicorn/workers.py", line 66, in init_process
    super(UvicornWorker, self).init_process()
  File "/usr/local/lib/python3.9/site-packages/gunicorn/workers/base.py", line 134, in init_process
    self.load_wsgi()
  File "/usr/local/lib/python3.9/site-packages/gunicorn/workers/base.py", line 146, in load_wsgi
    self.wsgi = self.app.wsgi()
  File "/usr/local/lib/python3.9/site-packages/gunicorn/app/base.py", line 67, in wsgi
    self.callable = self.load()
  File "/usr/local/lib/python3.9/site-packages/gunicorn/app/wsgiapp.py", line 58, in load
    return self.load_wsgiapp()
  File "/usr/local/lib/python3.9/site-packages/gunicorn/app/wsgiapp.py", line 48, in load_wsgiapp
    return util.import_app(self.app_uri)
  File "/usr/local/lib/python3.9/site-packages/gunicorn/util.py", line 371, in import_app
    mod = importlib.import_module(module)
  File "/usr/local/lib/python3.9/importlib/__init__.py", line 127, in import_module
    return _bootstrap._gcd_import(name[level:], package, level)
  File "<frozen importlib._bootstrap>", line 1030, in _gcd_import
  File "<frozen importlib._bootstrap>", line 1007, in _find_and_load
  File "<frozen importlib._bootstrap>", line 986, in _find_and_load_unlocked
  File "<frozen importlib._bootstrap>", line 680, in _load_unlocked
  File "<frozen importlib._bootstrap_external>", line 850, in exec_module
  File "<frozen importlib._bootstrap>", line 228, in _call_with_frames_removed
  File "/app/app/main.py", line 9, in <module>
    from app.api import auth, dashboard, config, backup, archives, restore, schedule, logs, settings, health, events, repositories, ssh_keys
  File "/app/app/api/dashboard.py", line 11, in <module>
    from app.database.models import User, BackupJob, ScheduledJob, SystemLog
ImportError: cannot import name 'ScheduledJob' from 'app.database.models' (/app/app/database/models.py)
[2025-08-10 16:24:05 +0530] [13] [INFO] Worker exiting (pid: 13)
[2025-08-10 16:24:05 +0530] [1] [ERROR] Worker (pid:13) exited with code 3
[2025-08-10 16:24:05 +0530] [1] [ERROR] Worker (pid:12) was sent SIGTERM!
[2025-08-10 16:24:05 +0530] [1] [ERROR] Shutting down: Master
[2025-08-10 16:24:05 +0530] [1] [ERROR] Reason: Worker failed to boot.
[2025-08-10 16:24:09 +0530] [1] [INFO] Starting gunicorn 21.2.0
[2025-08-10 16:24:09 +0530] [1] [INFO] Listening at: http://0.0.0.0:8000 (1)
[2025-08-10 16:24:09 +0530] [1] [INFO] Using worker: uvicorn.workers.UvicornWorker
[2025-08-10 16:24:09 +0530] [12] [INFO] Booting worker with pid: 12
[2025-08-10 16:24:09 +0530] [13] [INFO] Booting worker with pid: 13
[2025-08-10 16:24:10 +0530] [12] [ERROR] Exception in worker process
Traceback (most recent call last):
  File "/usr/local/lib/python3.9/site-packages/gunicorn/arbiter.py", line 609, in spawn_worker
    worker.init_process()
  File "/usr/local/lib/python3.9/site-packages/uvicorn/workers.py", line 66, in init_process
    super(UvicornWorker, self).init_process()
  File "/usr/local/lib/python3.9/site-packages/gunicorn/workers/base.py", line 134, in init_process
    self.load_wsgi()
  File "/usr/local/lib/python3.9/site-packages/gunicorn/workers/base.py", line 146, in load_wsgi
    self.wsgi = self.app.wsgi()
  File "/usr/local/lib/python3.9/site-packages/gunicorn/app/base.py", line 67, in wsgi
    self.callable = self.load()
  File "/usr/local/lib/python3.9/site-packages/gunicorn/app/wsgiapp.py", line 58, in load
    return self.load_wsgiapp()
  File "/usr/local/lib/python3.9/site-packages/gunicorn/app/wsgiapp.py", line 48, in load_wsgiapp
    return util.import_app(self.app_uri)
  File "/usr/local/lib/python3.9/site-packages/gunicorn/util.py", line 371, in import_app
    mod = importlib.import_module(module)
  File "/usr/local/lib/python3.9/importlib/__init__.py", line 127, in import_module
    return _bootstrap._gcd_import(name[level:], package, level)
  File "<frozen importlib._bootstrap>", line 1030, in _gcd_import
  File "<frozen importlib._bootstrap>", line 1007, in _find_and_load
  File "<frozen importlib._bootstrap>", line 986, in _find_and_load_unlocked
  File "<frozen importlib._bootstrap>", line 680, in _load_unlocked
  File "<frozen importlib._bootstrap_external>", line 850, in exec_module
  File "<frozen importlib._bootstrap>", line 228, in _call_with_frames_removed
  File "/app/app/main.py", line 9, in <module>
    from app.api import auth, dashboard, config, backup, archives, restore, schedule, logs, settings, health, events, repositories, ssh_keys
  File "/app/app/api/dashboard.py", line 11, in <module>
    from app.database.models import User, BackupJob, ScheduledJob, SystemLog
ImportError: cannot import name 'ScheduledJob' from 'app.database.models' (/app/app/database/models.py)
[2025-08-10 16:24:10 +0530] [12] [INFO] Worker exiting (pid: 12)
[2025-08-10 16:24:10 +0530] [13] [ERROR] Exception in worker process
Traceback (most recent call last):
  File "/usr/local/lib/python3.9/site-packages/gunicorn/arbiter.py", line 609, in spawn_worker
    worker.init_process()
  File "/usr/local/lib/python3.9/site-packages/uvicorn/workers.py", line 66, in init_process
    super(UvicornWorker, self).init_process()
  File "/usr/local/lib/python3.9/site-packages/gunicorn/workers/base.py", line 134, in init_process
    self.load_wsgi()
  File "/usr/local/lib/python3.9/site-packages/gunicorn/workers/base.py", line 146, in load_wsgi
    self.wsgi = self.app.wsgi()
  File "/usr/local/lib/python3.9/site-packages/gunicorn/app/base.py", line 67, in wsgi
    self.callable = self.load()
  File "/usr/local/lib/python3.9/site-packages/gunicorn/app/wsgiapp.py", line 58, in load
    return self.load_wsgiapp()
  File "/usr/local/lib/python3.9/site-packages/gunicorn/app/wsgiapp.py", line 48, in load_wsgiapp
    return util.import_app(self.app_uri)
  File "/usr/local/lib/python3.9/site-packages/gunicorn/util.py", line 371, in import_app
    mod = importlib.import_module(module)
  File "/usr/local/lib/python3.9/importlib/__init__.py", line 127, in import_module
    return _bootstrap._gcd_import(name[level:], package, level)
  File "<frozen importlib._bootstrap>", line 1030, in _gcd_import
  File "<frozen importlib._bootstrap>", line 1007, in _find_and_load
  File "<frozen importlib._bootstrap>", line 986, in _find_and_load_unlocked
  File "<frozen importlib._bootstrap>", line 680, in _load_unlocked
  File "<frozen importlib._bootstrap_external>", line 850, in exec_module
  File "<frozen importlib._bootstrap>", line 228, in _call_with_frames_removed
  File "/app/app/main.py", line 9, in <module>
    from app.api import auth, dashboard, config, backup, archives, restore, schedule, logs, settings, health, events, repositories, ssh_keys
  File "/app/app/api/dashboard.py", line 11, in <module>
    from app.database.models import User, BackupJob, ScheduledJob, SystemLog
ImportError: cannot import name 'ScheduledJob' from 'app.database.models' (/app/app/database/models.py)
[2025-08-10 16:24:10 +0530] [13] [INFO] Worker exiting (pid: 13)
[2025-08-10 16:24:10 +0530] [1] [ERROR] Worker (pid:12) exited with code 3
[2025-08-10 16:24:10 +0530] [1] [ERROR] Worker (pid:13) was sent SIGTERM!
[2025-08-10 16:24:10 +0530] [1] [ERROR] Shutting down: Master
[2025-08-10 16:24:10 +0530] [1] [ERROR] Reason: Worker failed to boot.
[2025-08-10 16:24:17 +0530] [1] [INFO] Starting gunicorn 21.2.0
[2025-08-10 16:24:17 +0530] [1] [INFO] Listening at: http://0.0.0.0:8000 (1)
[2025-08-10 16:24:17 +0530] [1] [INFO] Using worker: uvicorn.workers.UvicornWorker
[2025-08-10 16:24:17 +0530] [12] [INFO] Booting worker with pid: 12
[2025-08-10 16:24:17 +0530] [13] [INFO] Booting worker with pid: 13
[2025-08-10 16:24:18 +0530] [12] [ERROR] Exception in worker process
Traceback (most recent call last):
  File "/usr/local/lib/python3.9/site-packages/gunicorn/arbiter.py", line 609, in spawn_worker
    worker.init_process()
  File "/usr/local/lib/python3.9/site-packages/uvicorn/workers.py", line 66, in init_process
    super(UvicornWorker, self).init_process()
  File "/usr/local/lib/python3.9/site-packages/gunicorn/workers/base.py", line 134, in init_process
    self.load_wsgi()
  File "/usr/local/lib/python3.9/site-packages/gunicorn/workers/base.py", line 146, in load_wsgi
    self.wsgi = self.app.wsgi()
  File "/usr/local/lib/python3.9/site-packages/gunicorn/app/base.py", line 67, in wsgi
    self.callable = self.load()
  File "/usr/local/lib/python3.9/site-packages/gunicorn/app/wsgiapp.py", line 58, in load
    return self.load_wsgiapp()
  File "/usr/local/lib/python3.9/site-packages/gunicorn/app/wsgiapp.py", line 48, in load_wsgiapp
    return util.import_app(self.app_uri)
  File "/usr/local/lib/python3.9/site-packages/gunicorn/util.py", line 371, in import_app
    mod = importlib.import_module(module)
  File "/usr/local/lib/python3.9/importlib/__init__.py", line 127, in import_module
    return _bootstrap._gcd_import(name[level:], package, level)
  File "<frozen importlib._bootstrap>", line 1030, in _gcd_import
  File "<frozen importlib._bootstrap>", line 1007, in _find_and_load
  File "<frozen importlib._bootstrap>", line 986, in _find_and_load_unlocked
  File "<frozen importlib._bootstrap>", line 680, in _load_unlocked
  File "<frozen importlib._bootstrap_external>", line 850, in exec_module
  File "<frozen importlib._bootstrap>", line 228, in _call_with_frames_removed
  File "/app/app/main.py", line 9, in <module>
    from app.api import auth, dashboard, config, backup, archives, restore, schedule, logs, settings, health, events, repositories, ssh_keys
  File "/app/app/api/dashboard.py", line 11, in <module>
    from app.database.models import User, BackupJob, ScheduledJob, SystemLog
ImportError: cannot import name 'ScheduledJob' from 'app.database.models' (/app/app/database/models.py)
[2025-08-10 16:24:18 +0530] [12] [INFO] Worker exiting (pid: 12)
[2025-08-10 16:24:18 +0530] [1] [ERROR] Worker (pid:12) exited with code 3
[2025-08-10 16:24:18 +0530] [1] [ERROR] Worker (pid:13) was sent SIGTERM!
[2025-08-10 16:24:18 +0530] [1] [ERROR] Shutting down: Master
[2025-08-10 16:24:18 +0530] [1] [ERROR] Reason: Worker failed to boot.
[2025-08-10 16:24:31 +0530] [1] [INFO] Starting gunicorn 21.2.0
[2025-08-10 16:24:31 +0530] [1] [INFO] Listening at: http://0.0.0.0:8000 (1)
[2025-08-10 16:24:31 +0530] [1] [INFO] Using worker: uvicorn.workers.UvicornWorker
[2025-08-10 16:24:31 +0530] [12] [INFO] Booting worker with pid: 12
[2025-08-10 16:24:31 +0530] [13] [INFO] Booting worker with pid: 13
[2025-08-10 16:24:32 +0530] [12] [ERROR] Exception in worker process
Traceback (most recent call last):
  File "/usr/local/lib/python3.9/site-packages/gunicorn/arbiter.py", line 609, in spawn_worker
    worker.init_process()
  File "/usr/local/lib/python3.9/site-packages/uvicorn/workers.py", line 66, in init_process
    super(UvicornWorker, self).init_process()
  File "/usr/local/lib/python3.9/site-packages/gunicorn/workers/base.py", line 134, in init_process
    self.load_wsgi()
  File "/usr/local/lib/python3.9/site-packages/gunicorn/workers/base.py", line 146, in load_wsgi
    self.wsgi = self.app.wsgi()
  File "/usr/local/lib/python3.9/site-packages/gunicorn/app/base.py", line 67, in wsgi
    self.callable = self.load()
  File "/usr/local/lib/python3.9/site-packages/gunicorn/app/wsgiapp.py", line 58, in load
    return self.load_wsgiapp()
  File "/usr/local/lib/python3.9/site-packages/gunicorn/app/wsgiapp.py", line 48, in load_wsgiapp
    return util.import_app(self.app_uri)
  File "/usr/local/lib/python3.9/site-packages/gunicorn/util.py", line 371, in import_app
    mod = importlib.import_module(module)
  File "/usr/local/lib/python3.9/importlib/__init__.py", line 127, in import_module
    return _bootstrap._gcd_import(name[level:], package, level)
  File "<frozen importlib._bootstrap>", line 1030, in _gcd_import
  File "<frozen importlib._bootstrap>", line 1007, in _find_and_load
  File "<frozen importlib._bootstrap>", line 986, in _find_and_load_unlocked
  File "<frozen importlib._bootstrap>", line 680, in _load_unlocked
  File "<frozen importlib._bootstrap_external>", line 850, in exec_module
  File "<frozen importlib._bootstrap>", line 228, in _call_with_frames_removed
  File "/app/app/main.py", line 9, in <module>
    from app.api import auth, dashboard, config, backup, archives, restore, schedule, logs, settings, health, events, repositories, ssh_keys
  File "/app/app/api/dashboard.py", line 11, in <module>
    from app.database.models import User, BackupJob, ScheduledJob, SystemLog
ImportError: cannot import name 'ScheduledJob' from 'app.database.models' (/app/app/database/models.py)
[2025-08-10 16:24:32 +0530] [12] [INFO] Worker exiting (pid: 12)
[2025-08-10 16:24:32 +0530] [1] [ERROR] Worker (pid:12) exited with code 3
[2025-08-10 16:24:32 +0530] [1] [ERROR] Worker (pid:13) was sent SIGTERM!
[2025-08-10 16:24:32 +0530] [1] [ERROR] Shutting down: Master
[2025-08-10 16:24:32 +0530] [1] [ERROR] Reason: Worker failed to boot.
[2025-08-10 16:42:44 +0530] [1] [INFO] Starting gunicorn 21.2.0
[2025-08-10 16:42:44 +0530] [1] [INFO] Listening at: http://0.0.0.0:8000 (1)
[2025-08-10 16:42:44 +0530] [1] [INFO] Using worker: uvicorn.workers.UvicornWorker
[2025-08-10 16:42:44 +0530] [12] [INFO] Booting worker with pid: 12
[2025-08-10 16:42:44 +0530] [13] [INFO] Booting worker with pid: 13
[2025-08-10 16:42:45 +0530] [12] [ERROR] Exception in worker process
Traceback (most recent call last):
  File "/usr/local/lib/python3.9/site-packages/gunicorn/arbiter.py", line 609, in spawn_worker
    worker.init_process()
  File "/usr/local/lib/python3.9/site-packages/uvicorn/workers.py", line 66, in init_process
    super(UvicornWorker, self).init_process()
  File "/usr/local/lib/python3.9/site-packages/gunicorn/workers/base.py", line 134, in init_process
    self.load_wsgi()
  File "/usr/local/lib/python3.9/site-packages/gunicorn/workers/base.py", line 146, in load_wsgi
    self.wsgi = self.app.wsgi()
  File "/usr/local/lib/python3.9/site-packages/gunicorn/app/base.py", line 67, in wsgi
    self.callable = self.load()
  File "/usr/local/lib/python3.9/site-packages/gunicorn/app/wsgiapp.py", line 58, in load
    return self.load_wsgiapp()
  File "/usr/local/lib/python3.9/site-packages/gunicorn/app/wsgiapp.py", line 48, in load_wsgiapp
    return util.import_app(self.app_uri)
  File "/usr/local/lib/python3.9/site-packages/gunicorn/util.py", line 371, in import_app
    mod = importlib.import_module(module)
  File "/usr/local/lib/python3.9/importlib/__init__.py", line 127, in import_module
    return _bootstrap._gcd_import(name[level:], package, level)
  File "<frozen importlib._bootstrap>", line 1030, in _gcd_import
  File "<frozen importlib._bootstrap>", line 1007, in _find_and_load
  File "<frozen importlib._bootstrap>", line 986, in _find_and_load_unlocked
  File "<frozen importlib._bootstrap>", line 680, in _load_unlocked
  File "<frozen importlib._bootstrap_external>", line 850, in exec_module
  File "<frozen importlib._bootstrap>", line 228, in _call_with_frames_removed
  File "/app/app/main.py", line 9, in <module>
    from app.api import auth, dashboard, config, backup, archives, restore, schedule, logs, settings, health, events, repositories
  File "/app/app/api/dashboard.py", line 11, in <module>
    from app.database.models import User, BackupJob, ScheduledJob, SystemLog
ImportError: cannot import name 'ScheduledJob' from 'app.database.models' (/app/app/database/models.py)
[2025-08-10 16:42:45 +0530] [12] [INFO] Worker exiting (pid: 12)
[2025-08-10 16:42:45 +0530] [1] [ERROR] Worker (pid:12) exited with code 3
[2025-08-10 16:42:45 +0530] [1] [ERROR] Worker (pid:13) was sent SIGTERM!
[2025-08-10 16:42:45 +0530] [1] [ERROR] Shutting down: Master
[2025-08-10 16:42:45 +0530] [1] [ERROR] Reason: Worker failed to boot.
[2025-08-10 16:42:45 +0530] [1] [INFO] Starting gunicorn 21.2.0
[2025-08-10 16:42:45 +0530] [1] [INFO] Listening at: http://0.0.0.0:8000 (1)
[2025-08-10 16:42:45 +0530] [1] [INFO] Using worker: uvicorn.workers.UvicornWorker
[2025-08-10 16:42:45 +0530] [12] [INFO] Booting worker with pid: 12
[2025-08-10 16:42:46 +0530] [13] [INFO] Booting worker with pid: 13
[2025-08-10 16:42:46 +0530] [12] [ERROR] Exception in worker process
Traceback (most recent call last):
  File "/usr/local/lib/python3.9/site-packages/gunicorn/arbiter.py", line 609, in spawn_worker
    worker.init_process()
  File "/usr/local/lib/python3.9/site-packages/uvicorn/workers.py", line 66, in init_process
    super(UvicornWorker, self).init_process()
  File "/usr/local/lib/python3.9/site-packages/gunicorn/workers/base.py", line 134, in init_process
    self.load_wsgi()
  File "/usr/local/lib/python3.9/site-packages/gunicorn/workers/base.py", line 146, in load_wsgi
    self.wsgi = self.app.wsgi()
  File "/usr/local/lib/python3.9/site-packages/gunicorn/app/base.py", line 67, in wsgi
    self.callable = self.load()
  File "/usr/local/lib/python3.9/site-packages/gunicorn/app/wsgiapp.py", line 58, in load
    return self.load_wsgiapp()
  File "/usr/local/lib/python3.9/site-packages/gunicorn/app/wsgiapp.py", line 48, in load_wsgiapp
    return util.import_app(self.app_uri)
  File "/usr/local/lib/python3.9/site-packages/gunicorn/util.py", line 371, in import_app
    mod = importlib.import_module(module)
  File "/usr/local/lib/python3.9/importlib/__init__.py", line 127, in import_module
    return _bootstrap._gcd_import(name[level:], package, level)
  File "<frozen importlib._bootstrap>", line 1030, in _gcd_import
  File "<frozen importlib._bootstrap>", line 1007, in _find_and_load
  File "<frozen importlib._bootstrap>", line 986, in _find_and_load_unlocked
  File "<frozen importlib._bootstrap>", line 680, in _load_unlocked
  File "<frozen importlib._bootstrap_external>", line 850, in exec_module
  File "<frozen importlib._bootstrap>", line 228, in _call_with_frames_removed
  File "/app/app/main.py", line 9, in <module>
    from app.api import auth, dashboard, config, backup, archives, restore, schedule, logs, settings, health, events, repositories
  File "/app/app/api/dashboard.py", line 11, in <module>
    from app.database.models import User, BackupJob, ScheduledJob, SystemLog
ImportError: cannot import name 'ScheduledJob' from 'app.database.models' (/app/app/database/models.py)
[2025-08-10 16:42:46 +0530] [12] [INFO] Worker exiting (pid: 12)
[2025-08-10 16:42:46 +0530] [1] [ERROR] Worker (pid:12) exited with code 3
[2025-08-10 16:42:46 +0530] [1] [ERROR] Worker (pid:13) was sent SIGTERM!
[2025-08-10 16:42:46 +0530] [1] [ERROR] Shutting down: Master
[2025-08-10 16:42:46 +0530] [1] [ERROR] Reason: Worker failed to boot.
[2025-08-10 16:42:47 +0530] [1] [INFO] Starting gunicorn 21.2.0
[2025-08-10 16:42:47 +0530] [1] [INFO] Listening at: http://0.0.0.0:8000 (1)
[2025-08-10 16:42:47 +0530] [1] [INFO] Using worker: uvicorn.workers.UvicornWorker
[2025-08-10 16:42:47 +0530] [12] [INFO] Booting worker with pid: 12
[2025-08-10 16:42:47 +0530] [13] [INFO] Booting worker with pid: 13
[2025-08-10 16:42:48 +0530] [12] [ERROR] Exception in worker process
Traceback (most recent call last):
  File "/usr/local/lib/python3.9/site-packages/gunicorn/arbiter.py", line 609, in spawn_worker
    worker.init_process()
  File "/usr/local/lib/python3.9/site-packages/uvicorn/workers.py", line 66, in init_process
    super(UvicornWorker, self).init_process()
  File "/usr/local/lib/python3.9/site-packages/gunicorn/workers/base.py", line 134, in init_process
    self.load_wsgi()
  File "/usr/local/lib/python3.9/site-packages/gunicorn/workers/base.py", line 146, in load_wsgi
    self.wsgi = self.app.wsgi()
  File "/usr/local/lib/python3.9/site-packages/gunicorn/app/base.py", line 67, in wsgi
    self.callable = self.load()
  File "/usr/local/lib/python3.9/site-packages/gunicorn/app/wsgiapp.py", line 58, in load
    return self.load_wsgiapp()
  File "/usr/local/lib/python3.9/site-packages/gunicorn/app/wsgiapp.py", line 48, in load_wsgiapp
    return util.import_app(self.app_uri)
  File "/usr/local/lib/python3.9/site-packages/gunicorn/util.py", line 371, in import_app
    mod = importlib.import_module(module)
  File "/usr/local/lib/python3.9/importlib/__init__.py", line 127, in import_module
    return _bootstrap._gcd_import(name[level:], package, level)
  File "<frozen importlib._bootstrap>", line 1030, in _gcd_import
  File "<frozen importlib._bootstrap>", line 1007, in _find_and_load
  File "<frozen importlib._bootstrap>", line 986, in _find_and_load_unlocked
  File "<frozen importlib._bootstrap>", line 680, in _load_unlocked
  File "<frozen importlib._bootstrap_external>", line 850, in exec_module
  File "<frozen importlib._bootstrap>", line 228, in _call_with_frames_removed
  File "/app/app/main.py", line 9, in <module>
    from app.api import auth, dashboard, config, backup, archives, restore, schedule, logs, settings, health, events, repositories
  File "/app/app/api/dashboard.py", line 11, in <module>
    from app.database.models import User, BackupJob, ScheduledJob, SystemLog
ImportError: cannot import name 'ScheduledJob' from 'app.database.models' (/app/app/database/models.py)
[2025-08-10 16:42:48 +0530] [12] [INFO] Worker exiting (pid: 12)
[2025-08-10 16:42:48 +0530] [1] [ERROR] Worker (pid:12) exited with code 3
[2025-08-10 16:42:48 +0530] [1] [ERROR] Worker (pid:13) was sent SIGTERM!
[2025-08-10 16:42:48 +0530] [1] [ERROR] Shutting down: Master
[2025-08-10 16:42:48 +0530] [1] [ERROR] Reason: Worker failed to boot.
[2025-08-10 16:42:49 +0530] [1] [INFO] Starting gunicorn 21.2.0
[2025-08-10 16:42:49 +0530] [1] [INFO] Listening at: http://0.0.0.0:8000 (1)
[2025-08-10 16:42:49 +0530] [1] [INFO] Using worker: uvicorn.workers.UvicornWorker
[2025-08-10 16:42:49 +0530] [12] [INFO] Booting worker with pid: 12
[2025-08-10 16:42:49 +0530] [13] [INFO] Booting worker with pid: 13
[2025-08-10 16:42:49 +0530] [12] [ERROR] Exception in worker process
Traceback (most recent call last):
  File "/usr/local/lib/python3.9/site-packages/gunicorn/arbiter.py", line 609, in spawn_worker
    worker.init_process()
  File "/usr/local/lib/python3.9/site-packages/uvicorn/workers.py", line 66, in init_process
    super(UvicornWorker, self).init_process()
  File "/usr/local/lib/python3.9/site-packages/gunicorn/workers/base.py", line 134, in init_process
    self.load_wsgi()
  File "/usr/local/lib/python3.9/site-packages/gunicorn/workers/base.py", line 146, in load_wsgi
    self.wsgi = self.app.wsgi()
  File "/usr/local/lib/python3.9/site-packages/gunicorn/app/base.py", line 67, in wsgi
    self.callable = self.load()
  File "/usr/local/lib/python3.9/site-packages/gunicorn/app/wsgiapp.py", line 58, in load
    return self.load_wsgiapp()
  File "/usr/local/lib/python3.9/site-packages/gunicorn/app/wsgiapp.py", line 48, in load_wsgiapp
    return util.import_app(self.app_uri)
  File "/usr/local/lib/python3.9/site-packages/gunicorn/util.py", line 371, in import_app
    mod = importlib.import_module(module)
  File "/usr/local/lib/python3.9/importlib/__init__.py", line 127, in import_module
    return _bootstrap._gcd_import(name[level:], package, level)
  File "<frozen importlib._bootstrap>", line 1030, in _gcd_import
  File "<frozen importlib._bootstrap>", line 1007, in _find_and_load
  File "<frozen importlib._bootstrap>", line 986, in _find_and_load_unlocked
  File "<frozen importlib._bootstrap>", line 680, in _load_unlocked
  File "<frozen importlib._bootstrap_external>", line 850, in exec_module
  File "<frozen importlib._bootstrap>", line 228, in _call_with_frames_removed
  File "/app/app/main.py", line 9, in <module>
    from app.api import auth, dashboard, config, backup, archives, restore, schedule, logs, settings, health, events, repositories
  File "/app/app/api/dashboard.py", line 11, in <module>
    from app.database.models import User, BackupJob, ScheduledJob, SystemLog
ImportError: cannot import name 'ScheduledJob' from 'app.database.models' (/app/app/database/models.py)
[2025-08-10 16:42:49 +0530] [12] [INFO] Worker exiting (pid: 12)
[2025-08-10 16:42:50 +0530] [1] [ERROR] Worker (pid:12) exited with code 3
[2025-08-10 16:42:50 +0530] [1] [ERROR] Worker (pid:13) was sent SIGTERM!
[2025-08-10 16:42:50 +0530] [1] [ERROR] Shutting down: Master
[2025-08-10 16:42:50 +0530] [1] [ERROR] Reason: Worker failed to boot.
[2025-08-10 16:42:51 +0530] [1] [INFO] Starting gunicorn 21.2.0
[2025-08-10 16:42:51 +0530] [1] [INFO] Listening at: http://0.0.0.0:8000 (1)
[2025-08-10 16:42:51 +0530] [1] [INFO] Using worker: uvicorn.workers.UvicornWorker
[2025-08-10 16:42:51 +0530] [12] [INFO] Booting worker with pid: 12
[2025-08-10 16:42:51 +0530] [13] [INFO] Booting worker with pid: 13
[2025-08-10 16:42:52 +0530] [12] [ERROR] Exception in worker process
Traceback (most recent call last):
  File "/usr/local/lib/python3.9/site-packages/gunicorn/arbiter.py", line 609, in spawn_worker
    worker.init_process()
  File "/usr/local/lib/python3.9/site-packages/uvicorn/workers.py", line 66, in init_process
    super(UvicornWorker, self).init_process()
  File "/usr/local/lib/python3.9/site-packages/gunicorn/workers/base.py", line 134, in init_process
    self.load_wsgi()
  File "/usr/local/lib/python3.9/site-packages/gunicorn/workers/base.py", line 146, in load_wsgi
    self.wsgi = self.app.wsgi()
  File "/usr/local/lib/python3.9/site-packages/gunicorn/app/base.py", line 67, in wsgi
    self.callable = self.load()
  File "/usr/local/lib/python3.9/site-packages/gunicorn/app/wsgiapp.py", line 58, in load
    return self.load_wsgiapp()
  File "/usr/local/lib/python3.9/site-packages/gunicorn/app/wsgiapp.py", line 48, in load_wsgiapp
    return util.import_app(self.app_uri)
  File "/usr/local/lib/python3.9/site-packages/gunicorn/util.py", line 371, in import_app
    mod = importlib.import_module(module)
  File "/usr/local/lib/python3.9/importlib/__init__.py", line 127, in import_module
    return _bootstrap._gcd_import(name[level:], package, level)
  File "<frozen importlib._bootstrap>", line 1030, in _gcd_import
  File "<frozen importlib._bootstrap>", line 1007, in _find_and_load
  File "<frozen importlib._bootstrap>", line 986, in _find_and_load_unlocked
  File "<frozen importlib._bootstrap>", line 680, in _load_unlocked
  File "<frozen importlib._bootstrap_external>", line 850, in exec_module
  File "<frozen importlib._bootstrap>", line 228, in _call_with_frames_removed
  File "/app/app/main.py", line 9, in <module>
    from app.api import auth, dashboard, config, backup, archives, restore, schedule, logs, settings, health, events, repositories
  File "/app/app/api/dashboard.py", line 11, in <module>
    from app.database.models import User, BackupJob, ScheduledJob, SystemLog
ImportError: cannot import name 'ScheduledJob' from 'app.database.models' (/app/app/database/models.py)
[2025-08-10 16:42:52 +0530] [12] [INFO] Worker exiting (pid: 12)
[2025-08-10 16:42:52 +0530] [13] [ERROR] Exception in worker process
Traceback (most recent call last):
  File "/usr/local/lib/python3.9/site-packages/gunicorn/arbiter.py", line 609, in spawn_worker
    worker.init_process()
  File "/usr/local/lib/python3.9/site-packages/uvicorn/workers.py", line 66, in init_process
    super(UvicornWorker, self).init_process()
  File "/usr/local/lib/python3.9/site-packages/gunicorn/workers/base.py", line 134, in init_process
    self.load_wsgi()
  File "/usr/local/lib/python3.9/site-packages/gunicorn/workers/base.py", line 146, in load_wsgi
    self.wsgi = self.app.wsgi()
  File "/usr/local/lib/python3.9/site-packages/gunicorn/app/base.py", line 67, in wsgi
    self.callable = self.load()
  File "/usr/local/lib/python3.9/site-packages/gunicorn/app/wsgiapp.py", line 58, in load
    return self.load_wsgiapp()
  File "/usr/local/lib/python3.9/site-packages/gunicorn/app/wsgiapp.py", line 48, in load_wsgiapp
    return util.import_app(self.app_uri)
  File "/usr/local/lib/python3.9/site-packages/gunicorn/util.py", line 371, in import_app
    mod = importlib.import_module(module)
  File "/usr/local/lib/python3.9/importlib/__init__.py", line 127, in import_module
    return _bootstrap._gcd_import(name[level:], package, level)
  File "<frozen importlib._bootstrap>", line 1030, in _gcd_import
  File "<frozen importlib._bootstrap>", line 1007, in _find_and_load
  File "<frozen importlib._bootstrap>", line 986, in _find_and_load_unlocked
  File "<frozen importlib._bootstrap>", line 680, in _load_unlocked
  File "<frozen importlib._bootstrap_external>", line 850, in exec_module
  File "<frozen importlib._bootstrap>", line 228, in _call_with_frames_removed
  File "/app/app/main.py", line 9, in <module>
    from app.api import auth, dashboard, config, backup, archives, restore, schedule, logs, settings, health, events, repositories
  File "/app/app/api/dashboard.py", line 11, in <module>
    from app.database.models import User, BackupJob, ScheduledJob, SystemLog
ImportError: cannot import name 'ScheduledJob' from 'app.database.models' (/app/app/database/models.py)
[2025-08-10 16:42:52 +0530] [13] [INFO] Worker exiting (pid: 13)
[2025-08-10 16:42:52 +0530] [1] [ERROR] Worker (pid:12) exited with code 3
[2025-08-10 16:42:52 +0530] [1] [ERROR] Worker (pid:13) was sent SIGTERM!
[2025-08-10 16:42:52 +0530] [1] [ERROR] Shutting down: Master
[2025-08-10 16:42:52 +0530] [1] [ERROR] Reason: Worker failed to boot.
[2025-08-10 16:42:54 +0530] [1] [INFO] Starting gunicorn 21.2.0
[2025-08-10 16:42:54 +0530] [1] [INFO] Listening at: http://0.0.0.0:8000 (1)
[2025-08-10 16:42:54 +0530] [1] [INFO] Using worker: uvicorn.workers.UvicornWorker
[2025-08-10 16:42:54 +0530] [12] [INFO] Booting worker with pid: 12
[2025-08-10 16:42:54 +0530] [13] [INFO] Booting worker with pid: 13
[2025-08-10 16:42:55 +0530] [12] [ERROR] Exception in worker process
Traceback (most recent call last):
  File "/usr/local/lib/python3.9/site-packages/gunicorn/arbiter.py", line 609, in spawn_worker
    worker.init_process()
  File "/usr/local/lib/python3.9/site-packages/uvicorn/workers.py", line 66, in init_process
    super(UvicornWorker, self).init_process()
  File "/usr/local/lib/python3.9/site-packages/gunicorn/workers/base.py", line 134, in init_process
    self.load_wsgi()
  File "/usr/local/lib/python3.9/site-packages/gunicorn/workers/base.py", line 146, in load_wsgi
    self.wsgi = self.app.wsgi()
  File "/usr/local/lib/python3.9/site-packages/gunicorn/app/base.py", line 67, in wsgi
    self.callable = self.load()
  File "/usr/local/lib/python3.9/site-packages/gunicorn/app/wsgiapp.py", line 58, in load
    return self.load_wsgiapp()
  File "/usr/local/lib/python3.9/site-packages/gunicorn/app/wsgiapp.py", line 48, in load_wsgiapp
    return util.import_app(self.app_uri)
  File "/usr/local/lib/python3.9/site-packages/gunicorn/util.py", line 371, in import_app
    mod = importlib.import_module(module)
  File "/usr/local/lib/python3.9/importlib/__init__.py", line 127, in import_module
    return _bootstrap._gcd_import(name[level:], package, level)
  File "<frozen importlib._bootstrap>", line 1030, in _gcd_import
  File "<frozen importlib._bootstrap>", line 1007, in _find_and_load
  File "<frozen importlib._bootstrap>", line 986, in _find_and_load_unlocked
  File "<frozen importlib._bootstrap>", line 680, in _load_unlocked
  File "<frozen importlib._bootstrap_external>", line 850, in exec_module
  File "<frozen importlib._bootstrap>", line 228, in _call_with_frames_removed
  File "/app/app/main.py", line 9, in <module>
    from app.api import auth, dashboard, config, backup, archives, restore, schedule, logs, settings, health, events, repositories
  File "/app/app/api/dashboard.py", line 11, in <module>
    from app.database.models import User, BackupJob, ScheduledJob, SystemLog
ImportError: cannot import name 'ScheduledJob' from 'app.database.models' (/app/app/database/models.py)
[2025-08-10 16:42:55 +0530] [12] [INFO] Worker exiting (pid: 12)
[2025-08-10 16:42:55 +0530] [1] [ERROR] Worker (pid:12) exited with code 3
[2025-08-10 16:42:55 +0530] [1] [ERROR] Worker (pid:13) was sent SIGTERM!
[2025-08-10 16:42:55 +0530] [1] [ERROR] Shutting down: Master
[2025-08-10 16:42:55 +0530] [1] [ERROR] Reason: Worker failed to boot.
[2025-08-10 16:42:59 +0530] [1] [INFO] Starting gunicorn 21.2.0
[2025-08-10 16:42:59 +0530] [1] [INFO] Listening at: http://0.0.0.0:8000 (1)
[2025-08-10 16:42:59 +0530] [1] [INFO] Using worker: uvicorn.workers.UvicornWorker
[2025-08-10 16:42:59 +0530] [11] [INFO] Booting worker with pid: 11
[2025-08-10 16:42:59 +0530] [12] [INFO] Booting worker with pid: 12
[2025-08-10 16:42:59 +0530] [12] [ERROR] Exception in worker process
Traceback (most recent call last):
  File "/usr/local/lib/python3.9/site-packages/gunicorn/arbiter.py", line 609, in spawn_worker
    worker.init_process()
  File "/usr/local/lib/python3.9/site-packages/uvicorn/workers.py", line 66, in init_process
    super(UvicornWorker, self).init_process()
  File "/usr/local/lib/python3.9/site-packages/gunicorn/workers/base.py", line 134, in init_process
    self.load_wsgi()
  File "/usr/local/lib/python3.9/site-packages/gunicorn/workers/base.py", line 146, in load_wsgi
    self.wsgi = self.app.wsgi()
  File "/usr/local/lib/python3.9/site-packages/gunicorn/app/base.py", line 67, in wsgi
    self.callable = self.load()
  File "/usr/local/lib/python3.9/site-packages/gunicorn/app/wsgiapp.py", line 58, in load
    return self.load_wsgiapp()
  File "/usr/local/lib/python3.9/site-packages/gunicorn/app/wsgiapp.py", line 48, in load_wsgiapp
    return util.import_app(self.app_uri)
  File "/usr/local/lib/python3.9/site-packages/gunicorn/util.py", line 371, in import_app
    mod = importlib.import_module(module)
  File "/usr/local/lib/python3.9/importlib/__init__.py", line 127, in import_module
    return _bootstrap._gcd_import(name[level:], package, level)
  File "<frozen importlib._bootstrap>", line 1030, in _gcd_import
  File "<frozen importlib._bootstrap>", line 1007, in _find_and_load
  File "<frozen importlib._bootstrap>", line 986, in _find_and_load_unlocked
  File "<frozen importlib._bootstrap>", line 680, in _load_unlocked
  File "<frozen importlib._bootstrap_external>", line 850, in exec_module
  File "<frozen importlib._bootstrap>", line 228, in _call_with_frames_removed
  File "/app/app/main.py", line 9, in <module>
    from app.api import auth, dashboard, config, backup, archives, restore, schedule, logs, settings, health, events, repositories
  File "/app/app/api/dashboard.py", line 11, in <module>
    from app.database.models import User, BackupJob, ScheduledJob, SystemLog
ImportError: cannot import name 'ScheduledJob' from 'app.database.models' (/app/app/database/models.py)
[2025-08-10 16:42:59 +0530] [12] [INFO] Worker exiting (pid: 12)
[2025-08-10 16:42:59 +0530] [11] [ERROR] Exception in worker process
Traceback (most recent call last):
  File "/usr/local/lib/python3.9/site-packages/gunicorn/arbiter.py", line 609, in spawn_worker
    worker.init_process()
  File "/usr/local/lib/python3.9/site-packages/uvicorn/workers.py", line 66, in init_process
    super(UvicornWorker, self).init_process()
  File "/usr/local/lib/python3.9/site-packages/gunicorn/workers/base.py", line 134, in init_process
    self.load_wsgi()
  File "/usr/local/lib/python3.9/site-packages/gunicorn/workers/base.py", line 146, in load_wsgi
    self.wsgi = self.app.wsgi()
  File "/usr/local/lib/python3.9/site-packages/gunicorn/app/base.py", line 67, in wsgi
    self.callable = self.load()
  File "/usr/local/lib/python3.9/site-packages/gunicorn/app/wsgiapp.py", line 58, in load
    return self.load_wsgiapp()
  File "/usr/local/lib/python3.9/site-packages/gunicorn/app/wsgiapp.py", line 48, in load_wsgiapp
    return util.import_app(self.app_uri)
  File "/usr/local/lib/python3.9/site-packages/gunicorn/util.py", line 371, in import_app
    mod = importlib.import_module(module)
  File "/usr/local/lib/python3.9/importlib/__init__.py", line 127, in import_module
    return _bootstrap._gcd_import(name[level:], package, level)
  File "<frozen importlib._bootstrap>", line 1030, in _gcd_import
  File "<frozen importlib._bootstrap>", line 1007, in _find_and_load
  File "<frozen importlib._bootstrap>", line 986, in _find_and_load_unlocked
  File "<frozen importlib._bootstrap>", line 680, in _load_unlocked
  File "<frozen importlib._bootstrap_external>", line 850, in exec_module
  File "<frozen importlib._bootstrap>", line 228, in _call_with_frames_removed
  File "/app/app/main.py", line 9, in <module>
    from app.api import auth, dashboard, config, backup, archives, restore, schedule, logs, settings, health, events, repositories
  File "/app/app/api/dashboard.py", line 11, in <module>
    from app.database.models import User, BackupJob, ScheduledJob, SystemLog
ImportError: cannot import name 'ScheduledJob' from 'app.database.models' (/app/app/database/models.py)
[2025-08-10 16:42:59 +0530] [11] [INFO] Worker exiting (pid: 11)
[2025-08-10 16:43:00 +0530] [1] [ERROR] Worker (pid:11) exited with code 3
[2025-08-10 16:43:00 +0530] [1] [ERROR] Worker (pid:12) was sent SIGTERM!
[2025-08-10 16:43:00 +0530] [1] [ERROR] Shutting down: Master
[2025-08-10 16:43:00 +0530] [1] [ERROR] Reason: Worker failed to boot.
[2025-08-10 16:51:11 +0530] [1] [INFO] Starting gunicorn 21.2.0
[2025-08-10 16:51:11 +0530] [1] [INFO] Listening at: http://0.0.0.0:8000 (1)
[2025-08-10 16:51:11 +0530] [1] [INFO] Using worker: uvicorn.workers.UvicornWorker
[2025-08-10 16:51:11 +0530] [11] [INFO] Booting worker with pid: 11
[2025-08-10 16:51:11 +0530] [12] [INFO] Booting worker with pid: 12
[2025-08-10 16:51:15 +0530] [11] [INFO] Started server process [11]
[2025-08-10 16:51:15 +0530] [12] [INFO] Started server process [12]
[2025-08-10 16:51:15 +0530] [11] [INFO] Waiting for application startup.
[2025-08-10 16:51:15 +0530] [12] [INFO] Waiting for application startup.
[2025-08-10 16:51:16 +0530] [11] [INFO] Application startup complete.
[2025-08-10 16:51:16 +0530] [12] [INFO] Application startup complete.
[2025-08-10 16:57:02 +0530] [1] [INFO] Handling signal: term
[2025-08-10 16:57:02 +0530] [12] [INFO] Shutting down
[2025-08-10 16:57:02 +0530] [12] [INFO] Error while closing socket [Errno 9] Bad file descriptor
[2025-08-10 16:57:02 +0530] [11] [INFO] Shutting down
[2025-08-10 16:57:02 +0530] [11] [INFO] Error while closing socket [Errno 9] Bad file descriptor
[2025-08-10 16:57:02 +0530] [12] [INFO] Waiting for application shutdown.
[2025-08-10 16:57:02 +0530] [11] [INFO] Waiting for application shutdown.
[2025-08-10 16:57:02 +0530] [12] [INFO] Application shutdown complete.
[2025-08-10 16:57:02 +0530] [12] [INFO] Finished server process [12]
[2025-08-10 16:57:02 +0530] [11] [INFO] Application shutdown complete.
[2025-08-10 16:57:02 +0530] [11] [INFO] Finished server process [11]
[2025-08-10 16:57:02 +0530] [12] [INFO] Worker exiting (pid: 12)
[2025-08-10 16:57:02 +0530] [11] [INFO] Worker exiting (pid: 11)
[2025-08-10 16:57:02 +0530] [1] [INFO] Shutting down: Master
[2025-08-10 16:57:03 +0530] [1] [INFO] Starting gunicorn 21.2.0
[2025-08-10 16:57:03 +0530] [1] [INFO] Listening at: http://0.0.0.0:8000 (1)
[2025-08-10 16:57:03 +0530] [1] [INFO] Using worker: uvicorn.workers.UvicornWorker
[2025-08-10 16:57:03 +0530] [12] [INFO] Booting worker with pid: 12
[2025-08-10 16:57:03 +0530] [13] [INFO] Booting worker with pid: 13
[2025-08-10 16:57:07 +0530] [13] [INFO] Started server process [13]
[2025-08-10 16:57:07 +0530] [13] [INFO] Waiting for application startup.
[2025-08-10 16:57:07 +0530] [12] [INFO] Started server process [12]
[2025-08-10 16:57:07 +0530] [12] [INFO] Waiting for application startup.
[2025-08-10 16:57:07 +0530] [12] [INFO] Application startup complete.
[2025-08-10 16:57:07 +0530] [13] [INFO] Application startup complete.
